Workbook

Sheet sap nuevo
A1: Nº doc. | B1: Fecha doc. | C1: Importe en ML | D1: Usuario | E1: numero de cheque | F1: importe | G1: Fe.valor | H1: Banco | I1: pagado | J1: estado | K1: estado dos | L1: estado tres | M1: en cartera | N1: semana | O1: mes | P1: AÑO | Q1: periodo | R1: semana actual | T1: FECHA DE CORTE | U1: HOY | V1: =+IF(U1="HOY",Y1,AA1) -> 46272 | X1: HOY | Y1: =+TODAY() -> 46272 | Z1: CIERRE | AA1: 44629
A2: 3000000005 | B2: 45660 | C2: 1996725.8 | D2: ASOC.ARG.PROT.OBTENCIONES VEGECIUDAD AUTONOMA DE BUENOS AIRES 01 | E2: 3111702 | F2: 1996725.8 | G2: 45660 | H2: HSBC | I2: =IFERROR(IF(VLOOKUP(E2,extracto!C:C,1,FALSE)=E2,"pagado","no pagado"),"no pagado") -> pagado | J2: =IF(I2="pagado","pagado",IF(G2<$V$1-30,"fuera de fecha","en periodo de pago")) -> pagado | K2: =+IF(B2>$V$1,"excluir",IF(J2="en periodo de pago",IF($V$1>G2,"a pagar","proximo a vencer"),"excluir")) -> excluir | L2: =+IF(K2="proximo a vencer",IF($V$1+5>G2,"para la semana","no semana"),"no semana") -> no semana | M2: =IFERROR(VLOOKUP(E2,'cheques a conf'!A:D,4,FALSE),"no clearing") -> no clearing | N2: =+WEEKNUM(G2,2) -> 1 | O2: =+MONTH(G2) -> 1 | P2: =+YEAR(G2) -> 2025
A3: 3000000006 | B3: 45660 | C3: 3586921.4 | D3: YUNGAS AGROINSUMOS S.A YERBA BUENA 14 | E3: 3111703 | F3: 3586921.4 | G3: 45660 | H3: HSBC | I3: =IFERROR(IF(VLOOKUP(E3,extracto!C:C,1,FALSE)=E3,"pagado","no pagado"),"no pagado") -> pagado | J3: =IF(I3="pagado","pagado",IF(G3<$V$1-30,"fuera de fecha","en periodo de pago")) -> pagado | K3: =+IF(B3>$V$1,"excluir",IF(J3="en periodo de pago",IF($V$1>G3,"a pagar","proximo a vencer"),"excluir")) -> excluir | L3: =+IF(K3="proximo a vencer",IF($V$1+5>G3,"para la semana","no semana"),"no semana") -> no semana | M3: =IFERROR(VLOOKUP(E3,'cheques a conf'!A:D,4,FALSE),"no clearing") -> no clearing | N3: =+WEEKNUM(G3,2) -> 1 | O3: =+MONTH(G3) -> 1 | P3: =+YEAR(G3) -> 2025
A4: 3000000034 | B4: 45665 | C4: 2000000 | D4: Pulmajo S.R.L. CONCEPCION 14 | E4: 94231468 | F4: 2000000 | G4: 45667 | H4: HSBC | I4: =IFERROR(IF(VLOOKUP(E4,extracto!C:C,1,FALSE)=E4,"pagado","no pagado"),"no pagado") -> pagado | J4: =IF(I4="pagado","pagado",IF(G4<$V$1-30,"fuera de fecha","en periodo de pago")) -> pagado | K4: =+IF(B4>$V$1,"excluir",IF(J4="en periodo de pago",IF($V$1>G4,"a pagar","proximo a vencer"),"excluir")) -> excluir | L4: =+IF(K4="proximo a vencer",IF($V$1+5>G4,"para la semana","no semana"),"no semana") -> no semana | M4: =IFERROR(VLOOKUP(E4,'cheques a conf'!A:D,4,FALSE),"no clearing") -> no clearing | N4: =+WEEKNUM(G4,2) -> 2 | O4: =+MONTH(G4) -> 1 | P4: =+YEAR(G4) -> 2025
A5: 3000000034 | B5: 45665 | C5: 2000000 | D5: Pulmajo S.R.L. CONCEPCION 14 | E5: 94231469 | F5: 2000000 | G5: 45667 | H5: HSBC | I5: =IFERROR(IF(VLOOKUP(E5,extracto!C:C,1,FALSE)=E5,"pagado","no pagado"),"no pagado") -> pagado | J5: =IF(I5="pagado","pagado",IF(G5<$V$1-30,"fuera de fecha","en periodo de pago")) -> pagado | K5: =+IF(B5>$V$1,"excluir",IF(J5="en periodo de pago",IF($V$1>G5,"a pagar","proximo a vencer"),"excluir")) -> excluir | L5: =+IF(K5="proximo a vencer",IF($V$1+5>G5,"para la semana","no semana"),"no semana") -> no semana | M5: =IFERROR(VLOOKUP(E5,'cheques a conf'!A:D,4,FALSE),"no clearing") -> no clearing | N5: =+WEEKNUM(G5,2) -> 2 | O5: =+MONTH(G5) -> 1 | P5: =+YEAR(G5) -> 2025
A6: 3000000034 | B6: 45665 | C6: 2000000 | D6: Pulmajo S.R.L. CONCEPCION 14 | E6: 94231470 | F6: 2000000 | G6: 45667 | H6: HSBC | I6: =IFERROR(IF(VLOOKUP(E6,extracto!C:C,1,FALSE)=E6,"pagado","no pagado"),"no pagado") -> pagado | J6: =IF(I6="pagado","pagado",IF(G6<$V$1-30,"fuera de fecha","en periodo de pago")) -> pagado | K6: =+IF(B6>$V$1,"excluir",IF(J6="en periodo de pago",IF($V$1>G6,"a pagar","proximo a vencer"),"excluir")) -> excluir | L6: =+IF(K6="proximo a vencer",IF($V$1+5>G6,"para la semana","no semana"),"no semana") -> no semana | M6: =IFERROR(VLOOKUP(E6,'cheques a conf'!A:D,4,FALSE),"no clearing") -> no clearing | N6: =+WEEKNUM(G6,2) -> 2 | O6: =+MONTH(G6) -> 1 | P6: =+YEAR(G6) -> 2025
A7: 3000000034 | B7: 45665 | C7: 3000000 | D7: Pulmajo S.R.L. CONCEPCION 14 | E7: 94231471 | F7: 3000000 | G7: 45667 | H7: HSBC | I7: =IFERROR(IF(VLOOKUP(E7,extracto!C:C,1,FALSE)=E7,"pagado","no pagado"),"no pagado") -> pagado | J7: =IF(I7="pagado","pagado",IF(G7<$V$1-30,"fuera de fecha","en periodo de pago")) -> pagado | K7: =+IF(B7>$V$1,"excluir",IF(J7="en periodo de pago",IF($V$1>G7,"a pagar","proximo a vencer"),"excluir")) -> excluir | L7: =+IF(K7="proximo a vencer",IF($V$1+5>G7,"para la semana","no semana"),"no semana") -> no semana | M7: =IFERROR(VLOOKUP(E7,'cheques a conf'!A:D,4,FALSE),"no clearing") -> no clearing | N7: =+WEEKNUM(G7,2) -> 2 | O7: =+MONTH(G7) -> 1 | P7: =+YEAR(G7) -> 2025
A8: 3000000034 | B8: 45665 | C8: 3000000 | D8: Pulmajo S.R.L. CONCEPCION 14 | E8: 94231472 | F8: 3000000 | G8: 45667 | H8: HSBC | I8: =IFERROR(IF(VLOOKUP(E8,extracto!C:C,1,FALSE)=E8,"pagado","no pagado"),"no pagado") -> pagado | J8: =IF(I8="pagado","pagado",IF(G8<$V$1-30,"fuera de fecha","en periodo de pago")) -> pagado | K8: =+IF(B8>$V$1,"excluir",IF(J8="en periodo de pago",IF($V$1>G8,"a pagar","proximo a vencer"),"excluir")) -> excluir | L8: =+IF(K8="proximo a vencer",IF($V$1+5>G8,"para la semana","no semana"),"no semana") -> no semana | M8: =IFERROR(VLOOKUP(E8,'cheques a conf'!A:D,4,FALSE),"no clearing") -> no clearing | N8: =+WEEKNUM(G8,2) -> 2 | O8: =+MONTH(G8) -> 1 | P8: =+YEAR(G8) -> 2025
A9: 3000000034 | B9: 45665 | C9: 3000000 | D9: Pulmajo S.R.L. CONCEPCION 14 | E9: 94231473 | F9: 3000000 | G9: 45667 | H9: HSBC | I9: =IFERROR(IF(VLOOKUP(E9,extracto!C:C,1,FALSE)=E9,"pagado","no pagado"),"no pagado") -> pagado | J9: =IF(I9="pagado","pagado",IF(G9<$V$1-30,"fuera de fecha","en periodo de pago")) -> pagado | K9: =+IF(B9>$V$1,"excluir",IF(J9="en periodo de pago",IF($V$1>G9,"a pagar","proximo a vencer"),"excluir")) -> excluir | L9: =+IF(K9="proximo a vencer",IF($V$1+5>G9,"para la semana","no semana"),"no semana") -> no semana | M9: =IFERROR(VLOOKUP(E9,'cheques a conf'!A:D,4,FALSE),"no clearing") -> no clearing | N9: =+WEEKNUM(G9,2) -> 2 | O9: =+MONTH(G9) -> 1 | P9: =+YEAR(G9) -> 2025
A10: 3000000034 | B10: 45665 | C10: 3846551.5 | D10: Pulmajo S.R.L. CONCEPCION 14 | E10: 94231474 | F10: 3846551.5 | G10: 45670 | H10: HSBC | I10: =IFERROR(IF(VLOOKUP(E10,extracto!C:C,1,FALSE)=E10,"pagado","no pagado"),"no pagado") -> pagado | J10: =IF(I10="pagado","pagado",IF(G10<$V$1-30,"fuera de fecha","en periodo de pago")) -> pagado | K10: =+IF(B10>$V$1,"excluir",IF(J10="en periodo de pago",IF($V$1>G10,"a pagar","proximo a vencer"),"excluir")) -> excluir | L10: =+IF(K10="proximo a vencer",IF($V$1+5>G10,"para la semana","no semana"),"no semana") -> no semana | M10: =IFERROR(VLOOKUP(E10,'cheques a conf'!A:D,4,FALSE),"no clearing") -> no clearing | N10: =+WEEKNUM(G10,2) -> 3 | O10: =+MONTH(G10) -> 1 | P10: =+YEAR(G10) -> 2025
A11: 3000000034 | B11: 45665 | C11: 5000000 | D11: Pulmajo S.R.L. CONCEPCION 14 | E11: 94231475 | F11: 5000000 | G11: 45670 | H11: HSBC | I11: =IFERROR(IF(VLOOKUP(E11,extracto!C:C,1,FALSE)=E11,"pagado","no pagado"),"no pagado") -> pagado | J11: =IF(I11="pagado","pagado",IF(G11<$V$1-30,"fuera de fecha","en periodo de pago")) -> pagado | K11: =+IF(B11>$V$1,"excluir",IF(J11="en periodo de pago",IF($V$1>G11,"a pagar","proximo a vencer"),"excluir")) -> excluir | L11: =+IF(K11="proximo a vencer",IF($V$1+5>G11,"para la semana","no semana"),"no semana") -> no semana | M11: =IFERROR(VLOOKUP(E11,'cheques a conf'!A:D,4,FALSE),"no clearing") -> no clearing | N11: =+WEEKNUM(G11,2) -> 3 | O11: =+MONTH(G11) -> 1 | P11: =+YEAR(G11) -> 2025
A12: 3000000034 | B12: 45665 | C12: 5000000 | D12: Pulmajo S.R.L. CONCEPCION 14 | E12: 94231476 | F12: 5000000 | G12: 45670 | H12: HSBC | I12: =IFERROR(IF(VLOOKUP(E12,extracto!C:C,1,FALSE)=E12,"pagado","no pagado"),"no pagado") -> pagado | J12: =IF(I12="pagado","pagado",IF(G12<$V$1-30,"fuera de fecha","en periodo de pago")) -> pagado | K12: =+IF(B12>$V$1,"excluir",IF(J12="en periodo de pago",IF($V$1>G12,"a pagar","proximo a vencer"),"excluir")) -> excluir | L12: =+IF(K12="proximo a vencer",IF($V$1+5>G12,"para la semana","no semana"),"no semana") -> no semana | M12: =IFERROR(VLOOKUP(E12,'cheques a conf'!A:D,4,FALSE),"no clearing") -> no clearing | N12: =+WEEKNUM(G12,2) -> 3 | O12: =+MONTH(G12) -> 1 | P12: =+YEAR(G12) -> 2025
A13: 3000000030 | B13: 45665 | C13: 5005406.9 | D13: MOYANO JULIO CESAR BANDA DEL RIO SALI 14 | E13: 97123392 | F13: 5005406.9 | G13: 45667 | H13: MACRO | I13: =IFERROR(IF(VLOOKUP(E13,extracto!C:C,1,FALSE)=E13,"pagado","no pagado"),"no pagado") -> pagado | J13: =IF(I13="pagado","pagado",IF(G13<$V$1-30,"fuera de fecha","en periodo de pago")) -> pagado | K13: =+IF(B13>$V$1,"excluir",IF(J13="en periodo de pago",IF($V$1>G13,"a pagar","proximo a vencer"),"excluir")) -> excluir | L13: =+IF(K13="proximo a vencer",IF($V$1+5>G13,"para la semana","no semana"),"no semana") -> no semana | M13: =IFERROR(VLOOKUP(E13,'cheques a conf'!A:D,4,FALSE),"no clearing") -> no clearing | N13: =+WEEKNUM(G13,2) -> 2 | O13: =+MONTH(G13) -> 1 | P13: =+YEAR(G13) -> 2025
... A859: 3000001669 | B859: 45980 | C859: 3708431.3 | D859: GUIFFREY MARCELO GUSTAVO VILLA ELISA 05 | E859: 97124048 | F859: 3708431.3 | G859: 45990 | H859: MACRO | I859: =IFERROR(IF(VLOOKUP(E859,extracto!C:C,1,FALSE)=E859,"pagado","no pagado"),"no pagado") -> pagado | J859: =IF(I859="pagado","pagado",IF(G859<$V$1-30,"fuera de fecha","en periodo de pago")) -> pagado | K859: =+IF(B859>$V$1,"excluir",IF(J859="en periodo de pago",IF($V$1>G859,"a pagar","proximo a vencer"),"excluir")) -> excluir | L859: =+IF(K859="proximo a vencer",IF($V$1+5>G859,"para la semana","no semana"),"no semana") -> no semana | M859: =IFERROR(VLOOKUP(E859,'cheques a conf'!A:D,4,FALSE),"no clearing") -> no clearing | N859: =+WEEKNUM(G859,2) -> 48 | O859: =+MONTH(G859) -> 11 | P859: =+YEAR(G859) -> 2025
A860: 3000001695 | B860: 45992 | D860: Anulado | E860: 97124049 | F860: 0 | G860: 46000 | H860: MACRO | I860: =IFERROR(IF(VLOOKUP(E860,extracto!C:C,1,FALSE)=E860,"pagado","no pagado"),"no pagado") -> no pagado | J860: =IF(I860="pagado","pagado",IF(G860<$V$1-30,"fuera de fecha","en periodo de pago")) -> fuera de fecha | K860: =+IF(B860>$V$1,"excluir",IF(J860="en periodo de pago",IF($V$1>G860,"a pagar","proximo a vencer"),"excluir")) -> excluir | L860: =+IF(K860="proximo a vencer",IF($V$1+5>G860,"para la semana","no semana"),"no semana") -> no semana | M860: =IFERROR(VLOOKUP(E860,'cheques a conf'!A:D,4,FALSE),"no clearing") -> no clearing | N860: =+WEEKNUM(G860,2) -> 50 | O860: =+MONTH(G860) -> 12 | P860: =+YEAR(G860) -> 2025
A861: 3000001696 | B861: 45992 | C861: 10615597 | D861: DANIEL MARCELO GUERRERO ALDERETES 14 | E861: 97124050 | F861: 10615597 | G861: 46000 | H861: MACRO | I861: =IFERROR(IF(VLOOKUP(E861,extracto!C:C,1,FALSE)=E861,"pagado","no pagado"),"no pagado") -> no pagado | J861: =IF(I861="pagado","pagado",IF(G861<$V$1-30,"fuera de fecha","en periodo de pago")) -> fuera de fecha | K861: =+IF(B861>$V$1,"excluir",IF(J861="en periodo de pago",IF($V$1>G861,"a pagar","proximo a vencer"),"excluir")) -> excluir | L861: =+IF(K861="proximo a vencer",IF($V$1+5>G861,"para la semana","no semana"),"no semana") -> no semana | M861: =IFERROR(VLOOKUP(E861,'cheques a conf'!A:D,4,FALSE),"no clearing") -> no clearing | N861: =+WEEKNUM(G861,2) -> 50 | O861: =+MONTH(G861) -> 12 | P861: =+YEAR(G861) -> 2025
A862: 3000001697 | B862: 45992 | C862: 12703204 | D862: EMPRENDIMIENTOS ASSUN S.A. SANTIAGO DEL ESTERO 13 | E862: 97124051 | F862: 12703204 | G862: 46000 | H862: MACRO | I862: =IFERROR(IF(VLOOKUP(E862,extracto!C:C,1,FALSE)=E862,"pagado","no pagado"),"no pagado") -> pagado | J862: =IF(I862="pagado","pagado",IF(G862<$V$1-30,"fuera de fecha","en periodo de pago")) -> pagado | K862: =+IF(B862>$V$1,"excluir",IF(J862="en periodo de pago",IF($V$1>G862,"a pagar","proximo a vencer"),"excluir")) -> excluir | L862: =+IF(K862="proximo a vencer",IF($V$1+5>G862,"para la semana","no semana"),"no semana") -> no semana | M862: =IFERROR(VLOOKUP(E862,'cheques a conf'!A:D,4,FALSE),"no clearing") -> no clearing | N862: =+WEEKNUM(G862,2) -> 50 | O862: =+MONTH(G862) -> 12 | P862: =+YEAR(G862) -> 2025
A863: 3000001698 | B863: 45992 | C863: 3133343.4 | D863: SALTOS JOSUE GONZALO NUEVA ESPERANZA 13 | E863: 97124052 | F863: 3133343.4 | G863: 46000 | H863: MACRO | I863: =IFERROR(IF(VLOOKUP(E863,extracto!C:C,1,FALSE)=E863,"pagado","no pagado"),"no pagado") -> pagado | J863: =IF(I863="pagado","pagado",IF(G863<$V$1-30,"fuera de fecha","en periodo de pago")) -> pagado | K863: =+IF(B863>$V$1,"excluir",IF(J863="en periodo de pago",IF($V$1>G863,"a pagar","proximo a vencer"),"excluir")) -> excluir | L863: =+IF(K863="proximo a vencer",IF($V$1+5>G863,"para la semana","no semana"),"no semana") -> no semana | M863: =IFERROR(VLOOKUP(E863,'cheques a conf'!A:D,4,FALSE),"no clearing") -> no clearing | N863: =+WEEKNUM(G863,2) -> 50 | O863: =+MONTH(G863) -> 12 | P863: =+YEAR(G863) -> 2025
A864: 3000001699 | B864: 45992 | C864: 3994274.9 | D864: GDM ARGENTINA SA Chacabuco 01 | E864: 97124053 | F864: 3994274.9 | G864: 46000 | H864: MACRO | I864: =IFERROR(IF(VLOOKUP(E864,extracto!C:C,1,FALSE)=E864,"pagado","no pagado"),"no pagado") -> pagado | J864: =IF(I864="pagado","pagado",IF(G864<$V$1-30,"fuera de fecha","en periodo de pago")) -> pagado | K864: =+IF(B864>$V$1,"excluir",IF(J864="en periodo de pago",IF($V$1>G864,"a pagar","proximo a vencer"),"excluir")) -> excluir | L864: =+IF(K864="proximo a vencer",IF($V$1+5>G864,"para la semana","no semana"),"no semana") -> no semana | M864: =IFERROR(VLOOKUP(E864,'cheques a conf'!A:D,4,FALSE),"no clearing") -> no clearing | N864: =+WEEKNUM(G864,2) -> 50 | O864: =+MONTH(G864) -> 12 | P864: =+YEAR(G864) -> 2025
A865: 3000001700 | B865: 45992 | C865: 13302378 | D865: GOMEZ JESSICA NOELIA LAS TALITAS 14 | E865: 97124054 | F865: 13302378 | G865: 46001 | H865: MACRO | I865: =IFERROR(IF(VLOOKUP(E865,extracto!C:C,1,FALSE)=E865,"pagado","no pagado"),"no pagado") -> pagado | J865: =IF(I865="pagado","pagado",IF(G865<$V$1-30,"fuera de fecha","en periodo de pago")) -> pagado | K865: =+IF(B865>$V$1,"excluir",IF(J865="en periodo de pago",IF($V$1>G865,"a pagar","proximo a vencer"),"excluir")) -> excluir | L865: =+IF(K865="proximo a vencer",IF($V$1+5>G865,"para la semana","no semana"),"no semana") -> no semana | M865: =IFERROR(VLOOKUP(E865,'cheques a conf'!A:D,4,FALSE),"no clearing") -> no clearing | N865: =+WEEKNUM(G865,2) -> 50 | O865: =+MONTH(G865) -> 12 | P865: =+YEAR(G865) -> 2025
A866: 3000001701 | B866: 45992 | C866: 6789793.4 | D866: SERVICOM S.R.L SAN MIGUEL DE TUCUMAN 14 | E866: 97124055 | F866: 6789793.4 | G866: 46001 | H866: MACRO | I866: =IFERROR(IF(VLOOKUP(E866,extracto!C:C,1,FALSE)=E866,"pagado","no pagado"),"no pagado") -> pagado | J866: =IF(I866="pagado","pagado",IF(G866<$V$1-30,"fuera de fecha","en periodo de pago")) -> pagado | K866: =+IF(B866>$V$1,"excluir",IF(J866="en periodo de pago",IF($V$1>G866,"a pagar","proximo a vencer"),"excluir")) -> excluir | L866: =+IF(K866="proximo a vencer",IF($V$1+5>G866,"para la semana","no semana"),"no semana") -> no semana | M866: =IFERROR(VLOOKUP(E866,'cheques a conf'!A:D,4,FALSE),"no clearing") -> no clearing | N866: =+WEEKNUM(G866,2) -> 50 | O866: =+MONTH(G866) -> 12 | P866: =+YEAR(G866) -> 2025
A867: 3000001702 | B867: 45992 | C867: 4297443.4 | D867: UDRIZARD VIVIANA ISABEL CONCORDIA 05 | E867: 97124056 | F867: 4297443.4 | G867: 46001 | H867: MACRO | I867: =IFERROR(IF(VLOOKUP(E867,extracto!C:C,1,FALSE)=E867,"pagado","no pagado"),"no pagado") -> pagado | J867: =IF(I867="pagado","pagado",IF(G867<$V$1-30,"fuera de fecha","en periodo de pago")) -> pagado | K867: =+IF(B867>$V$1,"excluir",IF(J867="en periodo de pago",IF($V$1>G867,"a pagar","proximo a vencer"),"excluir")) -> excluir | L867: =+IF(K867="proximo a vencer",IF($V$1+5>G867,"para la semana","no semana"),"no semana") -> no semana | M867: =IFERROR(VLOOKUP(E867,'cheques a conf'!A:D,4,FALSE),"no clearing") -> no clearing | N867: =+WEEKNUM(G867,2) -> 50 | O867: =+MONTH(G867) -> 12 | P867: =+YEAR(G867) -> 2025
A868: 3000001703 | B868: 45992 | C868: 24755560 | D868: SALTOS JOSUE GONZALO NUEVA ESPERANZA 13 | E868: 97124057 | F868: 24755560 | G868: 46001 | H868: MACRO | I868: =IFERROR(IF(VLOOKUP(E868,extracto!C:C,1,FALSE)=E868,"pagado","no pagado"),"no pagado") -> pagado | J868: =IF(I868="pagado","pagado",IF(G868<$V$1-30,"fuera de fecha","en periodo de pago")) -> pagado | K868: =+IF(B868>$V$1,"excluir",IF(J868="en periodo de pago",IF($V$1>G868,"a pagar","proximo a vencer"),"excluir")) -> excluir | L868: =+IF(K868="proximo a vencer",IF($V$1+5>G868,"para la semana","no semana"),"no semana") -> no semana | M868: =IFERROR(VLOOKUP(E868,'cheques a conf'!A:D,4,FALSE),"no clearing") -> no clearing | N868: =+WEEKNUM(G868,2) -> 50 | O868: =+MONTH(G868) -> 12 | P868: =+YEAR(G868) -> 2025
A869: 3000001704 | B869: 45992 | C869: 4600000 | D869: Pulmajo S.R.L. CONCEPCION 14 | E869: 97124058 | F869: 4600000 | G869: 46001 | H869: MACRO | I869: =IFERROR(IF(VLOOKUP(E869,extracto!C:C,1,FALSE)=E869,"pagado","no pagado"),"no pagado") -> pagado | J869: =IF(I869="pagado","pagado",IF(G869<$V$1-30,"fuera de fecha","en periodo de pago")) -> pagado | K869: =+IF(B869>$V$1,"excluir",IF(J869="en periodo de pago",IF($V$1>G869,"a pagar","proximo a vencer"),"excluir")) -> excluir | L869: =+IF(K869="proximo a vencer",IF($V$1+5>G869,"para la semana","no semana"),"no semana") -> no semana | M869: =IFERROR(VLOOKUP(E869,'cheques a conf'!A:D,4,FALSE),"no clearing") -> no clearing | N869: =+WEEKNUM(G869,2) -> 50 | O869: =+MONTH(G869) -> 12 | P869: =+YEAR(G869) -> 2025
A870: 3000001704 | B870: 45992 | C870: 3000000 | D870: Pulmajo S.R.L. CONCEPCION 14 | E870: 97124059 | F870: 3000000 | G870: 46001 | H870: MACRO | I870: =IFERROR(IF(VLOOKUP(E870,extracto!C:C,1,FALSE)=E870,"pagado","no pagado"),"no pagado") -> pagado | J870: =IF(I870="pagado","pagado",IF(G870<$V$1-30,"fuera de fecha","en periodo de pago")) -> pagado | K870: =+IF(B870>$V$1,"excluir",IF(J870="en periodo de pago",IF($V$1>G870,"a pagar","proximo a vencer"),"excluir")) -> excluir | L870: =+IF(K870="proximo a vencer",IF($V$1+5>G870,"para la semana","no semana"),"no semana") -> no semana | M870: =IFERROR(VLOOKUP(E870,'cheques a conf'!A:D,4,FALSE),"no clearing") -> no clearing | N870: =+WEEKNUM(G870,2) -> 50 | O870: =+MONTH(G870) -> 12 | P870: =+YEAR(G870) -> 2025
A871: 3000001704 | B871: 45992 | C871: 5000000 | D871: Pulmajo S.R.L. CONCEPCION 14 | E871: 97124060 | F871: 5000000 | G871: 46001 | H871: MACRO | I871: =IFERROR(IF(VLOOKUP(E871,extracto!C:C,1,FALSE)=E871,"pagado","no pagado"),"no pagado") -> pagado | J871: =IF(I871="pagado","pagado",IF(G871<$V$1-30,"fuera de fecha","en periodo de pago")) -> pagado | K871: =+IF(B871>$V$1,"excluir",IF(J871="en periodo de pago",IF($V$1>G871,"a pagar","proximo a vencer"),"excluir")) -> excluir | L871: =+IF(K871="proximo a vencer",IF($V$1+5>G871,"para la semana","no semana"),"no semana") -> no semana | M871: =IFERROR(VLOOKUP(E871,'cheques a conf'!A:D,4,FALSE),"no clearing") -> no clearing | N871: =+WEEKNUM(G871,2) -> 50 | O871: =+MONTH(G871) -> 12 | P871: =+YEAR(G871) -> 2025
A872: 3000001704 | B872: 45992 | C872: 5000000 | D872: Pulmajo S.R.L. CONCEPCION 14 | E872: 97124061 | F872: 5000000 | G872: 46001 | H872: MACRO | I872: =IFERROR(IF(VLOOKUP(E872,extracto!C:C,1,FALSE)=E872,"pagado","no pagado"),"no pagado") -> pagado | J872: =IF(I872="pagado","pagado",IF(G872<$V$1-30,"fuera de fecha","en periodo de pago")) -> pagado | K872: =+IF(B872>$V$1,"excluir",IF(J872="en periodo de pago",IF($V$1>G872,"a pagar","proximo a vencer"),"excluir")) -> excluir | L872: =+IF(K872="proximo a vencer",IF($V$1+5>G872,"para la semana","no semana"),"no semana") -> no semana | M872: =IFERROR(VLOOKUP(E872,'cheques a conf'!A:D,4,FALSE),"no clearing") -> no clearing | N872: =+WEEKNUM(G872,2) -> 50 | O872: =+MONTH(G872) -> 12 | P872: =+YEAR(G872) -> 2025
... A1479: 3000001237 | B1479: 46267 | C1479: 44769026 | D1479: GOMEZ JESSICA NOELIA LAS TALITAS 14 | E1479: 97124656 | F1479: 44769026 | G1479: 46273 | H1479: MACRO | I1479: =IFERROR(IF(VLOOKUP(E1479,extracto!C:C,1,FALSE)=E1479,"pagado","no pagado"),"no pagado") -> no pagado | J1479: =IF(I1479="pagado","pagado",IF(G1479<$V$1-30,"fuera de fecha","en periodo de pago")) -> en periodo de pago | K1479: =+IF(B1479>$V$1,"excluir",IF(J1479="en periodo de pago",IF($V$1>G1479,"a pagar","proximo a vencer"),"excluir")) -> proximo a vencer | L1479: =+IF(K1479="proximo a vencer",IF($V$1+5>G1479,"para la semana","no semana"),"no semana") -> para la semana | M1479: =IFERROR(VLOOKUP(E1479,'cheques a conf'!A:D,4,FALSE),"no clearing") -> no clearing | N1479: =+WEEKNUM(G1479,2) -> 37 | O1479: =+MONTH(G1479) -> 9 | P1479: =+YEAR(G1479) -> 2026
I1480: =IFERROR(IF(VLOOKUP(E1480,extracto!C:C,1,FALSE)=E1480,"pagado","no pagado"),"no pagado") -> no pagado | J1480: =IF(I1480="pagado","pagado",IF(G1480<$V$1-30,"fuera de fecha","en periodo de pago")) -> fuera de fecha | K1480: =+IF(B1480>$V$1,"excluir",IF(J1480="en periodo de pago",IF($V$1>G1480,"a pagar","proximo a vencer"),"excluir")) -> excluir | L1480: =+IF(K1480="proximo a vencer",IF($V$1+5>G1480,"para la semana","no semana"),"no semana") -> no semana | M1480: =IFERROR(VLOOKUP(E1480,'cheques a conf'!A:D,4,FALSE),"no clearing") -> no clearing | N1480: =+WEEKNUM(G1480,2) -> 1 | O1480: =+MONTH(G1480) -> 1 | P1480: =+YEAR(G1480) -> 1900
I1481: =IFERROR(IF(VLOOKUP(E1481,extracto!C:C,1,FALSE)=E1481,"pagado","no pagado"),"no pagado") -> no pagado | J1481: =IF(I1481="pagado","pagado",IF(G1481<$V$1-30,"fuera de fecha","en periodo de pago")) -> fuera de fecha | K1481: =+IF(B1481>$V$1,"excluir",IF(J1481="en periodo de pago",IF($V$1>G1481,"a pagar","proximo a vencer"),"excluir")) -> excluir | L1481: =+IF(K1481="proximo a vencer",IF($V$1+5>G1481,"para la semana","no semana"),"no semana") -> no semana | M1481: =IFERROR(VLOOKUP(E1481,'cheques a conf'!A:D,4,FALSE),"no clearing") -> no clearing | N1481: =+WEEKNUM(G1481,2) -> 1 | O1481: =+MONTH(G1481) -> 1 | P1481: =+YEAR(G1481) -> 1900
I1482: =IFERROR(IF(VLOOKUP(E1482,extracto!C:C,1,FALSE)=E1482,"pagado","no pagado"),"no pagado") -> no pagado | J1482: =IF(I1482="pagado","pagado",IF(G1482<$V$1-30,"fuera de fecha","en periodo de pago")) -> fuera de fecha | K1482: =+IF(B1482>$V$1,"excluir",IF(J1482="en periodo de pago",IF($V$1>G1482,"a pagar","proximo a vencer"),"excluir")) -> excluir | L1482: =+IF(K1482="proximo a vencer",IF($V$1+5>G1482,"para la semana","no semana"),"no semana") -> no semana | M1482: =IFERROR(VLOOKUP(E1482,'cheques a conf'!A:D,4,FALSE),"no clearing") -> no clearing | N1482: =+WEEKNUM(G1482,2) -> 1 | O1482: =+MONTH(G1482) -> 1 | P1482: =+YEAR(G1482) -> 1900
I1483: =IFERROR(IF(VLOOKUP(E1483,extracto!C:C,1,FALSE)=E1483,"pagado","no pagado"),"no pagado") -> no pagado | J1483: =IF(I1483="pagado","pagado",IF(G1483<$V$1-30,"fuera de fecha","en periodo de pago")) -> fuera de fecha | K1483: =+IF(B1483>$V$1,"excluir",IF(J1483="en periodo de pago",IF($V$1>G1483,"a pagar","proximo a vencer"),"excluir")) -> excluir | L1483: =+IF(K1483="proximo a vencer",IF($V$1+5>G1483,"para la semana","no semana"),"no semana") -> no semana | M1483: =IFERROR(VLOOKUP(E1483,'cheques a conf'!A:D,4,FALSE),"no clearing") -> no clearing | N1483: =+WEEKNUM(G1483,2) -> 1 | O1483: =+MONTH(G1483) -> 1 | P1483: =+YEAR(G1483) -> 1900
I1484: =IFERROR(IF(VLOOKUP(E1484,extracto!C:C,1,FALSE)=E1484,"pagado","no pagado"),"no pagado") -> no pagado | J1484: =IF(I1484="pagado","pagado",IF(G1484<$V$1-30,"fuera de fecha","en periodo de pago")) -> fuera de fecha | K1484: =+IF(B1484>$V$1,"excluir",IF(J1484="en periodo de pago",IF($V$1>G1484,"a pagar","proximo a vencer"),"excluir")) -> excluir | L1484: =+IF(K1484="proximo a vencer",IF($V$1+5>G1484,"para la semana","no semana"),"no semana") -> no semana | M1484: =IFERROR(VLOOKUP(E1484,'cheques a conf'!A:D,4,FALSE),"no clearing") -> no clearing | N1484: =+WEEKNUM(G1484,2) -> 1 | O1484: =+MONTH(G1484) -> 1 | P1484: =+YEAR(G1484) -> 1900
I1485: =IFERROR(IF(VLOOKUP(E1485,extracto!C:C,1,FALSE)=E1485,"pagado","no pagado"),"no pagado") -> no pagado | J1485: =IF(I1485="pagado","pagado",IF(G1485<$V$1-30,"fuera de fecha","en periodo de pago")) -> fuera de fecha | K1485: =+IF(B1485>$V$1,"excluir",IF(J1485="en periodo de pago",IF($V$1>G1485,"a pagar","proximo a vencer"),"excluir")) -> excluir | L1485: =+IF(K1485="proximo a vencer",IF($V$1+5>G1485,"para la semana","no semana"),"no semana") -> no semana | M1485: =IFERROR(VLOOKUP(E1485,'cheques a conf'!A:D,4,FALSE),"no clearing") -> no clearing | N1485: =+WEEKNUM(G1485,2) -> 1 | O1485: =+MONTH(G1485) -> 1 | P1485: =+YEAR(G1485) -> 1900
I1486: =IFERROR(IF(VLOOKUP(E1486,extracto!C:C,1,FALSE)=E1486,"pagado","no pagado"),"no pagado") -> no pagado | J1486: =IF(I1486="pagado","pagado",IF(G1486<$V$1-30,"fuera de fecha","en periodo de pago")) -> fuera de fecha | K1486: =+IF(B1486>$V$1,"excluir",IF(J1486="en periodo de pago",IF($V$1>G1486,"a pagar","proximo a vencer"),"excluir")) -> excluir | L1486: =+IF(K1486="proximo a vencer",IF($V$1+5>G1486,"para la semana","no semana"),"no semana") -> no semana | M1486: =IFERROR(VLOOKUP(E1486,'cheques a conf'!A:D,4,FALSE),"no clearing") -> no clearing | N1486: =+WEEKNUM(G1486,2) -> 1 | O1486: =+MONTH(G1486) -> 1 | P1486: =+YEAR(G1486) -> 1900
I1487: =IFERROR(IF(VLOOKUP(E1487,extracto!C:C,1,FALSE)=E1487,"pagado","no pagado"),"no pagado") -> no pagado | J1487: =IF(I1487="pagado","pagado",IF(G1487<$V$1-30,"fuera de fecha","en periodo de pago")) -> fuera de fecha | K1487: =+IF(B1487>$V$1,"excluir",IF(J1487="en periodo de pago",IF($V$1>G1487,"a pagar","proximo a vencer"),"excluir")) -> excluir | L1487: =+IF(K1487="proximo a vencer",IF($V$1+5>G1487,"para la semana","no semana"),"no semana") -> no semana | M1487: =IFERROR(VLOOKUP(E1487,'cheques a conf'!A:D,4,FALSE),"no clearing") -> no clearing | N1487: =+WEEKNUM(G1487,2) -> 1 | O1487: =+MONTH(G1487) -> 1 | P1487: =+YEAR(G1487) -> 1900
I1488: =IFERROR(IF(VLOOKUP(E1488,extracto!C:C,1,FALSE)=E1488,"pagado","no pagado"),"no pagado") -> no pagado | J1488: =IF(I1488="pagado","pagado",IF(G1488<$V$1-30,"fuera de fecha","en periodo de pago")) -> fuera de fecha | K1488: =+IF(B1488>$V$1,"excluir",IF(J1488="en periodo de pago",IF($V$1>G1488,"a pagar","proximo a vencer"),"excluir")) -> excluir | L1488: =+IF(K1488="proximo a vencer",IF($V$1+5>G1488,"para la semana","no semana"),"no semana") -> no semana | M1488: =IFERROR(VLOOKUP(E1488,'cheques a conf'!A:D,4,FALSE),"no clearing") -> no clearing | N1488: =+WEEKNUM(G1488,2) -> 1 | O1488: =+MONTH(G1488) -> 1 | P1488: =+YEAR(G1488) -> 1900
I1489: =IFERROR(IF(VLOOKUP(E1489,extracto!C:C,1,FALSE)=E1489,"pagado","no pagado"),"no pagado") -> no pagado | J1489: =IF(I1489="pagado","pagado",IF(G1489<$V$1-30,"fuera de fecha","en periodo de pago")) -> fuera de fecha | K1489: =+IF(B1489>$V$1,"excluir",IF(J1489="en periodo de pago",IF($V$1>G1489,"a pagar","proximo a vencer"),"excluir")) -> excluir | L1489: =+IF(K1489="proximo a vencer",IF($V$1+5>G1489,"para la semana","no semana"),"no semana") -> no semana | M1489: =IFERROR(VLOOKUP(E1489,'cheques a conf'!A:D,4,FALSE),"no clearing") -> no clearing | N1489: =+WEEKNUM(G1489,2) -> 1 | O1489: =+MONTH(G1489) -> 1 | P1489: =+YEAR(G1489) -> 1900
I1490: =IFERROR(IF(VLOOKUP(E1490,extracto!C:C,1,FALSE)=E1490,"pagado","no pagado"),"no pagado") -> no pagado | J1490: =IF(I1490="pagado","pagado",IF(G1490<$V$1-30,"fuera de fecha","en periodo de pago")) -> fuera de fecha | K1490: =+IF(B1490>$V$1,"excluir",IF(J1490="en periodo de pago",IF($V$1>G1490,"a pagar","proximo a vencer"),"excluir")) -> excluir | L1490: =+IF(K1490="proximo a vencer",IF($V$1+5>G1490,"para la semana","no semana"),"no semana") -> no semana | M1490: =IFERROR(VLOOKUP(E1490,'cheques a conf'!A:D,4,FALSE),"no clearing") -> no clearing | N1490: =+WEEKNUM(G1490,2) -> 1 | O1490: =+MONTH(G1490) -> 1 | P1490: =+YEAR(G1490) -> 1900
I1491: =IFERROR(IF(VLOOKUP(E1491,extracto!C:C,1,FALSE)=E1491,"pagado","no pagado"),"no pagado") -> no pagado | J1491: =IF(I1491="pagado","pagado",IF(G1491<$V$1-30,"fuera de fecha","en periodo de pago")) -> fuera de fecha | K1491: =+IF(B1491>$V$1,"excluir",IF(J1491="en periodo de pago",IF($V$1>G1491,"a pagar","proximo a vencer"),"excluir")) -> excluir | L1491: =+IF(K1491="proximo a vencer",IF($V$1+5>G1491,"para la semana","no semana"),"no semana") -> no semana | M1491: =IFERROR(VLOOKUP(E1491,'cheques a conf'!A:D,4,FALSE),"no clearing") -> no clearing | N1491: =+WEEKNUM(G1491,2) -> 1 | O1491: =+MONTH(G1491) -> 1 | P1491: =+YEAR(G1491) -> 1900
...

Sheet extracto
A1: Concepto/Cod,Op, | B1: Fecha | C1: Comprobante | D1: Sucursal | E1: Importe | F1: Descripción | G1: Cod,Op,Bco, | I1: AÑO | J1: MES | M1: 1 | N1: 2 | O1: 3 | P1: 4 | Q1: 5 | R1: 6 | S1: 7 | T1: 8 | U1: 9 | V1: 10 | W1: 11 | X1: 12
A2: CH/RECIB48 | B2: 02/01/2025 | C2: 3111593 | D2: 52 | E2: -2.5316893e+08 | F2: CHEQUE 48 HORAS | G2: 2 | H2: =+IF(B2>'sap nuevo'!$V$1,"cargar",IF(C2="","cargar","pagado")) -> cargar | I2: =+YEAR(B2) -> 2025 | J2: =+MONTH(B2) -> 1
A3: CH/RECIB48 | B3: 02/01/2025 | C3: 3111695 | D3: 52 | E3: -9203500 | F3: CHEQUE 48 HORAS | G3: 2 | H3: =+IF(B3>'sap nuevo'!$V$1,"cargar",IF(C3="","cargar","pagado")) -> cargar | I3: =+YEAR(B3) -> 2025 | J3: =+MONTH(B3) -> 1
A4: CH/RECIB48 | B4: 02/01/2025 | C4: 3111690 | D4: 52 | E4: -8880365.6 | F4: CHEQUE 48 HORAS | G4: 2 | H4: =+IF(B4>'sap nuevo'!$V$1,"cargar",IF(C4="","cargar","pagado")) -> cargar | I4: =+YEAR(B4) -> 2025 | J4: =+MONTH(B4) -> 1
A5: CH/RECIB48 | B5: 02/01/2025 | C5: 3111689 | D5: 52 | E5: -8807343.4 | F5: CHEQUE 48 HORAS | G5: 2 | H5: =+IF(B5>'sap nuevo'!$V$1,"cargar",IF(C5="","cargar","pagado")) -> cargar | I5: =+YEAR(B5) -> 2025 | J5: =+MONTH(B5) -> 1
A6: CH/RECIB48 | B6: 02/01/2025 | C6: 3111691 | D6: 52 | E6: -8284097.7 | F6: CHEQUE 48 HORAS | G6: 2 | H6: =+IF(B6>'sap nuevo'!$V$1,"cargar",IF(C6="","cargar","pagado")) -> cargar | I6: =+YEAR(B6) -> 2025 | J6: =+MONTH(B6) -> 1
A7: CH/RECIB48 | B7: 02/01/2025 | C7: 3111685 | D7: 52 | E7: -5622006.8 | F7: CHEQUE 48 HORAS | G7: 2 | H7: =+IF(B7>'sap nuevo'!$V$1,"cargar",IF(C7="","cargar","pagado")) -> cargar | I7: =+YEAR(B7) -> 2025 | J7: =+MONTH(B7) -> 1
A8: CH/RECIB48 | B8: 02/01/2025 | C8: 3111692 | D8: 52 | E8: -4232237.9 | F8: CHEQUE 48 HORAS | G8: 2 | H8: =+IF(B8>'sap nuevo'!$V$1,"cargar",IF(C8="","cargar","pagado")) -> cargar | I8: =+YEAR(B8) -> 2025 | J8: =+MONTH(B8) -> 1
A9: CH/RECIB48 | B9: 02/01/2025 | C9: 94231447 | D9: 52 | E9: -300000 | F9: CHEQUE 48 HORAS | G9: 2 | H9: =+IF(B9>'sap nuevo'!$V$1,"cargar",IF(C9="","cargar","pagado")) -> cargar | I9: =+YEAR(B9) -> 2025 | J9: =+MONTH(B9) -> 1
A10: CH/RECIB48 | B10: 03/01/2025 | C10: 3111687 | D10: 52 | E10: -16439563 | F10: CHEQUE 48 HORAS | G10: 2 | H10: =+IF(B10>'sap nuevo'!$V$1,"cargar",IF(C10="","cargar","pagado")) -> cargar | I10: =+YEAR(B10) -> 2025 | J10: =+MONTH(B10) -> 1
A11: CH/RECIB48 | B11: 03/01/2025 | C11: 3111686 | D11: 52 | E11: -15000000 | F11: CHEQUE 48 HORAS | G11: 2 | H11: =+IF(B11>'sap nuevo'!$V$1,"cargar",IF(C11="","cargar","pagado")) -> cargar | I11: =+YEAR(B11) -> 2025 | J11: =+MONTH(B11) -> 1
A12: CH/RECIB48 | B12: 03/01/2025 | C12: 3111697 | D12: 52 | E12: -12656775 | F12: CHEQUE 48 HORAS | G12: 2 | H12: =+IF(B12>'sap nuevo'!$V$1,"cargar",IF(C12="","cargar","pagado")) -> cargar | I12: =+YEAR(B12) -> 2025 | J12: =+MONTH(B12) -> 1
A13: CH/RECIB48 | B13: 03/01/2025 | C13: 3111696 | D13: 52 | E13: -12000000 | F13: CHEQUE 48 HORAS | G13: 2 | H13: =+IF(B13>'sap nuevo'!$V$1,"cargar",IF(C13="","cargar","pagado")) -> cargar | I13: =+YEAR(B13) -> 2025 | J13: =+MONTH(B13) -> 1
... A72: CH/PAG | B72: 20/01/2025 | C72: 97123403 | D72: 140 | E72: -7956945.8 | F72: CHEQUE CANJE INTERNO | G72: 0 | H72: =+IF(B72>'sap nuevo'!$V$1,"cargar",IF(C72="","cargar","pagado")) -> cargar | I72: =+YEAR(B72) -> 2025 | J72: =+MONTH(B72) -> 1
A73: CH/RECIB48 | B73: 45679 | C73: 3111718 | D73: 52 | E73: -11200155 | F73: CHEQUE 48 HORAS | G73: 2 | H73: =+IF(B73>'sap nuevo'!$V$1,"cargar",IF(C73="","cargar","pagado")) -> pagado | I73: =+YEAR(B73) -> 2025 | J73: =+MONTH(B73) -> 1
A74: CH/RECIB48 | B74: 23/01/2025 | C74: 3111717 | D74: 52 | E74: -13410435 | F74: CHEQUE 48 HORAS | G74: 2 | H74: =+IF(B74>'sap nuevo'!$V$1,"cargar",IF(C74="","cargar","pagado")) -> cargar | I74: =+YEAR(B74) -> 2025 | J74: =+MONTH(B74) -> 1
A75: CH/RECIB48 | B75: 23/01/2025 | C75: 3111714 | D75: 52 | E75: -7648843.4 | F75: CHEQUE 48 HORAS | G75: 2 | H75: =+IF(B75>'sap nuevo'!$V$1,"cargar",IF(C75="","cargar","pagado")) -> cargar | I75: =+YEAR(B75) -> 2025 | J75: =+MONTH(B75) -> 1
A76: CH/RECIB48 | B76: 16/01/2025 | C76: 97123397 | D76: 140 | E76: -13000000 | F76: CHEQUE P/CAMARA | G76: 0 | H76: =+IF(B76>'sap nuevo'!$V$1,"cargar",IF(C76="","cargar","pagado")) -> cargar | I76: =+YEAR(B76) -> 2025 | J76: =+MONTH(B76) -> 1
A77: CH/RECIB48 | B77: 27/01/2025 | C77: 3111707 | D77: 52 | E77: -12595484 | F77: CHEQUE 48 HORAS | G77: 2 | H77: =+IF(B77>'sap nuevo'!$V$1,"cargar",IF(C77="","cargar","pagado")) -> cargar | I77: =+YEAR(B77) -> 2025 | J77: =+MONTH(B77) -> 1
A78: CH/RECIB48 | B78: 27/01/2025 | C78: 94231481 | D78: 52 | E78: -300000 | F78: CHEQUE 48 HORAS | G78: 2 | H78: =+IF(B78>'sap nuevo'!$V$1,"cargar",IF(C78="","cargar","pagado")) -> cargar | I78: =+YEAR(B78) -> 2025 | J78: =+MONTH(B78) -> 1
A79: CH/RECIB48 | B79: 27/01/2025 | C79: 94231482 | D79: 52 | E79: -300000 | F79: CHEQUE 48 HORAS | G79: 2 | H79: =+IF(B79>'sap nuevo'!$V$1,"cargar",IF(C79="","cargar","pagado")) -> cargar | I79: =+YEAR(B79) -> 2025 | J79: =+MONTH(B79) -> 1
A80: CH/RECIB48 | B80: 27/01/2025 | C80: 94231478 | D80: 52 | E80: -100000 | F80: CHEQUE 48 HORAS | G80: 2 | H80: =+IF(B80>'sap nuevo'!$V$1,"cargar",IF(C80="","cargar","pagado")) -> cargar | I80: =+YEAR(B80) -> 2025 | J80: =+MONTH(B80) -> 1
A81: CH/RECIB48 | B81: 28/01/2025 | C81: 3111725 | D81: 52 | E81: -15000000 | F81: CHEQUE 48 HORAS | G81: 2 | H81: =+IF(B81>'sap nuevo'!$V$1,"cargar",IF(C81="","cargar","pagado")) -> cargar | I81: =+YEAR(B81) -> 2025 | J81: =+MONTH(B81) -> 1
A82: CH/RECIB48 | B82: 28/01/2025 | C82: 3111723 | D82: 52 | E82: -11658151 | F82: CHEQUE 48 HORAS | G82: 2 | H82: =+IF(B82>'sap nuevo'!$V$1,"cargar",IF(C82="","cargar","pagado")) -> cargar | I82: =+YEAR(B82) -> 2025 | J82: =+MONTH(B82) -> 1
A83: CH/RECIB48 | B83: 28/01/2025 | C83: 3111715 | D83: 52 | E83: -6992278.8 | F83: CHEQUE 48 HORAS | G83: 2 | H83: =+IF(B83>'sap nuevo'!$V$1,"cargar",IF(C83="","cargar","pagado")) -> cargar | I83: =+YEAR(B83) -> 2025 | J83: =+MONTH(B83) -> 1
A84: CH/RECIB48 | B84: 28/01/2025 | C84: 3111729 | D84: 52 | E84: -6137336.1 | F84: CHEQUE 48 HORAS | G84: 2 | H84: =+IF(B84>'sap nuevo'!$V$1,"cargar",IF(C84="","cargar","pagado")) -> cargar | I84: =+YEAR(B84) -> 2025 | J84: =+MONTH(B84) -> 1
A85: CH/RECIB48 | B85: 28/01/2025 | C85: 94231502 | D85: 52 | E85: -5000000 | F85: CHEQUE 48 HORAS | G85: 2 | H85: =+IF(B85>'sap nuevo'!$V$1,"cargar",IF(C85="","cargar","pagado")) -> cargar | I85: =+YEAR(B85) -> 2025 | J85: =+MONTH(B85) -> 1
... A246: CH/PAG | B246: 20/03/2025 | C246: 97123437 | D246: 140 | E246: -9457422.2 | F246: CHEQUE CANJE INTERNO | G246: 0 | H246: =+IF(B246>'sap nuevo'!$V$1,"cargar",IF(C246="","cargar","pagado")) -> cargar | I246: =+YEAR(B246) -> 2025 | J246: =+MONTH(B246) -> 3
A247: CH/PAG | B247: 20/03/2025 | C247: 97123447 | D247: 140 | E247: -8531433.2 | F247: CHEQUE CANJE INTERNO | G247: 0 | H247: =+IF(#REF!>'sap nuevo'!$V$1,"cargar",IF(#REF!="","cargar","pagado")) -> #REF! | I247: =+YEAR(#REF!) -> #REF! | J247: =+MONTH(#REF!) -> #REF!
A248: CH/RECIB48 | B248: 20/03/2025 | C248: 97123451 | D248: 140 | E248: -7208101 | F248: CHEQUE P/CAMARA | G248: 0 | H248: =+IF(#REF!>'sap nuevo'!$V$1,"cargar",IF(#REF!="","cargar","pagado")) -> #REF! | I248: =+YEAR(#REF!) -> #REF! | J248: =+MONTH(#REF!) -> #REF!
A249: CH/RECIB48 | B249: 20/03/2025 | C249: 97123438 | D249: 140 | E249: -5586407.9 | F249: CHEQUE P/CAMARA | G249: 0 | H249: =+IF(#REF!>'sap nuevo'!$V$1,"cargar",IF(#REF!="","cargar","pagado")) -> #REF! | I249: =+YEAR(#REF!) -> #REF! | J249: =+MONTH(#REF!) -> #REF!
A250: CH/RECIB48 | B250: 21/03/2025 | C250: 94231523 | D250: 52 | E250: -13371410 | F250: CHEQUE 48 HORAS | G250: 2 | H250: =+IF(#REF!>'sap nuevo'!$V$1,"cargar",IF(#REF!="","cargar","pagado")) -> #REF! | I250: =+YEAR(#REF!) -> #REF! | J250: =+MONTH(#REF!) -> #REF!
A251: CH/RECIB48 | B251: 21/03/2025 | C251: 3400722 | D251: 52 | E251: -464138.31 | F251: CHEQUE 48 HORAS | G251: 2 | H251: =+IF(B251>'sap nuevo'!$V$1,"cargar",IF(C251="","cargar","pagado")) -> cargar | I251: =+YEAR(B251) -> 2025 | J251: =+MONTH(B251) -> 3
A252: CH/PAG | B252: 21/03/2025 | C252: 97123440 | D252: 140 | E252: -23741733 | F252: CHEQUE CANJE INTERNO | G252: 0 | H252: =+IF(B252>'sap nuevo'!$V$1,"cargar",IF(C252="","cargar","pagado")) -> cargar | I252: =+YEAR(B252) -> 2025 | J252: =+MONTH(B252) -> 3
A253: CH/RECIB48 | B253: 21/03/2025 | C253: 97123452 | D253: 140 | E253: -18687162 | F253: CHEQUE P/CAMARA | G253: 0 | H253: =+IF(B253>'sap nuevo'!$V$1,"cargar",IF(C253="","cargar","pagado")) -> cargar | I253: =+YEAR(B253) -> 2025 | J253: =+MONTH(B253) -> 3
A254: CH/PAG | B254: 21/03/2025 | C254: 97123435 | D254: 140 | E254: -12866828 | F254: CHEQUE CANJE INTERNO | G254: 0 | H254: =+IF(B254>'sap nuevo'!$V$1,"cargar",IF(C254="","cargar","pagado")) -> cargar | I254: =+YEAR(B254) -> 2025 | J254: =+MONTH(B254) -> 3
A255: CH/PAG | B255: 21/03/2025 | C255: 97123449 | D255: 140 | E255: -12146623 | F255: CHEQUE CANJE INTERNO | G255: 0 | H255: =+IF(B255>'sap nuevo'!$V$1,"cargar",IF(C255="","cargar","pagado")) -> cargar | I255: =+YEAR(B255) -> 2025 | J255: =+MONTH(B255) -> 3
A256: CH/RECIB48 | B256: 21/03/2025 | C256: 97123446 | D256: 140 | E256: -9215559 | F256: CHEQUE P/CAMARA | G256: 0 | H256: =+IF(B256>'sap nuevo'!$V$1,"cargar",IF(C256="","cargar","pagado")) -> cargar | I256: =+YEAR(B256) -> 2025 | J256: =+MONTH(B256) -> 3
A257: CH/RECIB48 | B257: 21/03/2025 | C257: 97123436 | D257: 140 | E257: -3640830.9 | F257: CHEQUE P/CAMARA | G257: 0 | H257: =+IF(B257>'sap nuevo'!$V$1,"cargar",IF(C257="","cargar","pagado")) -> cargar | I257: =+YEAR(B257) -> 2025 | J257: =+MONTH(B257) -> 3
A258: CH/RECIB48 | B258: 25/03/2025 | C258: 3111764 | D258: 52 | E258: -12029813 | F258: CHEQUE 48 HORAS | G258: 2 | H258: =+IF(B258>'sap nuevo'!$V$1,"cargar",IF(C258="","cargar","pagado")) -> cargar | I258: =+YEAR(B258) -> 2025 | J258: =+MONTH(B258) -> 3
...

Sheet cheques a conf
A1: Numero CH | B1: Fecha | C1: Importe | D1: Estado | E1: Banco
A2: 97124642 | B2: 04/09/202 | C2: -44935981 | D2: =+IF(A2="","cargar","clearing") -> clearing | E2: =VLOOKUP(A2,'sap nuevo'!E:H,4,FALSE) -> MACRO
A3: 97124643 | B3: 04/09/202 | C3: -6617092.5 | D3: =+IF(A3="","cargar","clearing") -> clearing | E3: =VLOOKUP(A3,'sap nuevo'!E:H,4,FALSE) -> MACRO
A4: 97124644 | B4: 04/09/202 | C4: -9242374.6 | D4: =+IF(A4="","cargar","clearing") -> clearing | E4: =VLOOKUP(A4,'sap nuevo'!E:H,4,FALSE) -> MACRO
A5: 97124645 | B5: 04/09/202 | C5: -6838598.5 | D5: =+IF(A5="","cargar","clearing") -> clearing | E5: =VLOOKUP(A5,'sap nuevo'!E:H,4,FALSE) -> MACRO
A6: 97124646 | B6: 04/09/202 | C6: -11569820 | D6: =+IF(A6="","cargar","clearing") -> clearing | E6: =VLOOKUP(A6,'sap nuevo'!E:H,4,FALSE) -> MACRO
A7: 97124647 | B7: 04/09/202 | C7: -12163460 | D7: =+IF(A7="","cargar","clearing") -> clearing | E7: =VLOOKUP(A7,'sap nuevo'!E:H,4,FALSE) -> MACRO
D8: =+IF(A8="","cargar","clearing") -> cargar | E8: =VLOOKUP(A8,'sap nuevo'!E:H,4,FALSE) -> #N/A
D9: =+IF(A9="","cargar","clearing") -> cargar | E9: =VLOOKUP(A9,'sap nuevo'!E:H,4,FALSE) -> #N/A
D10: =+IF(A10="","cargar","clearing") -> cargar | E10: =VLOOKUP(A10,'sap nuevo'!E:H,4,FALSE) -> #N/A
D11: =+IF(A11="","cargar","clearing") -> cargar | E11: =VLOOKUP(A11,'sap nuevo'!E:H,4,FALSE) -> #N/A
D12: =+IF(A12="","cargar","clearing") -> cargar | E12: =VLOOKUP(A12,'sap nuevo'!E:H,4,FALSE) -> #N/A
D13: =+IF(A13="","cargar","clearing") -> cargar | E13: =VLOOKUP(A13,'sap nuevo'!E:H,4,FALSE) -> #N/A
D14: =+IF(A14="","cargar","clearing") -> cargar | E14: =VLOOKUP(A14,'sap nuevo'!E:H,4,FALSE) -> #N/A
D15: =+IF(A15="","cargar","clearing") -> cargar | E15: =VLOOKUP(A15,'sap nuevo'!E:H,4,FALSE) -> #N/A
D16: =+IF(A16="","cargar","clearing") -> cargar | E16: =VLOOKUP(A16,'sap nuevo'!E:H,4,FALSE) -> #N/A
D17: =+IF(A17="","cargar","clearing") -> cargar | E17: =VLOOKUP(A17,'sap nuevo'!E:H,4,FALSE) -> #N/A
D18: =+IF(A18="","cargar","clearing") -> cargar | E18: =VLOOKUP(A18,'sap nuevo'!E:H,4,FALSE) -> #N/A
D19: =+IF(A19="","cargar","clearing") -> cargar | E19: =VLOOKUP(A19,'sap nuevo'!E:H,4,FALSE) -> #N/A
... D43: =+IF(A43="","cargar","clearing") -> cargar | E43: =VLOOKUP(A43,'sap nuevo'!E:H,4,FALSE) -> #N/A

Sheet resumen viejo
A1: EMPRESA: VILUCO SA | D1: - | E1: GALICIA | F1: MACRO | G1: Totales
A2: Cheques a Conformar | C2: =TODAY() -> 46272 | D2: 0 | E2: =IFERROR(GETPIVOTDATA("importe",$Q$12,"Banco","GALICIA"),0) -> 0 | F2: =IFERROR(GETPIVOTDATA("importe",$Q$12,"Banco","MACRO"),0) -> 91367327 | G2: =+D2+E2+F2 -> 91367327
A4: Cheques Pendientes al | C4: =+TODAY()-1 -> 46271 | D4: 0 | E4: =IFERROR(GETPIVOTDATA("importe",$A$13,"Banco","GALICIA")-E2, 0) -> 0 | F4: =IFERROR(GETPIVOTDATA("importe",$A$13,"Banco","MACRO")-F2,0) -> 1.7530124e+08 | G4: =+D4+E4+F4 -> 1.7530124e+08
A5: Cheques a Vencer Semana 07/09 al 11/09 | D5: 0 | E5: =SUM(K12) -> 0 | F5: =SUM(L14:L22) -> 1.317372e+08 | G5: =+D5+E5+F5 -> 1.317372e+08
A6: Cheques a Vencer Semana 14/09 al 18/09 | D6: 0 | E6: =SUM(K13) -> 0 | F6: =SUM(L13) -> 0 | G6: =+D6+E6+F6 -> 0
A7: Cheques a Vencer Semana 21/09 en adelante | D7: 0 | E7: =SUM(K13) -> 0 | F7: =SUM(L13) -> 0 | G7: =+D7+E7+F7 -> 0
A8: Totales | D8: =+D4+D5+D2+D6+D7 -> 0 | E8: =+E4+E5+E2+E6+E7 -> 0 | F8: =+F4+F5+F2+F6+F7 -> 3.9840576e+08 | G8: =+D8+E8+F8 -> 3.9840576e+08
J9: estado dos | K9: proximo a vencer | Q9: CHEQUES A PAGAR EN EL DÍA
A10: CHEQUES PENDIENTES POR COBRAR | J10: estado tres | K10: (Todas) | Q10: en cartera | R10: clearing
A11: estado dos | B11: a pagar
J12: Suma de importe | L12: Etiquetas de columna | Q12: Suma de importe | S12: Etiquetas de columna
A13: Suma de importe | C13: Etiquetas de columna | J13: Etiquetas de fila | K13: numero de cheque | L13: MACRO | M13: Total general | Q13: Etiquetas de fila | R13: Fe.valor | S13: MACRO | T13: Total general
A14: Etiquetas de fila | B14: Fe.valor | C14: MACRO | D14: Total general | J14: 46273 | K14: 97124648 | L14: 14441330 | M14: 14441330 | Q14: 97124642 | R14: 46269 | S14: 44935981 | T14: 44935981
A15: 97123951 | B15: 46270 | C15: 1.3543477e+08 | D15: 1.3543477e+08 | K15: 97124649 | L15: 9377491 | M15: 9377491 | Q15: 97124643 | R15: 46269 | S15: 6617092.5 | T15: 6617092.5
A16: 97124568 | B16: 46248 | C16: 24462703 | D16: 24462703 | K16: 97124650 | L16: 8437567.6 | M16: 8437567.6 | Q16: 97124644 | R16: 46269 | S16: 9242374.6 | T16: 9242374.6
A17: 97124635 | B17: 46267 | C17: 15403763 | D17: 15403763 | K17: 97124651 | L17: 22752607 | M17: 22752607 | Q17: 97124645 | R17: 46269 | S17: 6838598.5 | T17: 6838598.5
A18: 97124642 | B18: 46269 | C18: 44935981 | D18: 44935981 | K18: 97124652 | L18: 8576316.9 | M18: 8576316.9 | Q18: 97124646 | R18: 46269 | S18: 11569820 | T18: 11569820
A19: 97124643 | B19: 46269 | C19: 6617092.5 | D19: 6617092.5 | K19: 97124653 | L19: 9846655.2 | M19: 9846655.2 | Q19: 97124647 | R19: 46269 | S19: 12163460 | T19: 12163460
A20: 97124644 | B20: 46269 | C20: 9242374.6 | D20: 9242374.6 | K20: 97124654 | L20: 5962450.4 | M20: 5962450.4 | Q20: Total general | S20: 91367327 | T20: 91367327
A21: 97124645 | B21: 46269 | C21: 6838598.5 | D21: 6838598.5 | K21: 97124655 | L21: 7573756.1 | M21: 7573756.1
A22: 97124646 | B22: 46269 | C22: 11569820 | D22: 11569820 | K22: 97124656 | L22: 44769026 | M22: 44769026
A23: 97124647 | B23: 46269 | C23: 12163460 | D23: 12163460 | J23: Total general | L23: 1.317372e+08 | M23: 1.317372e+08
A24: Total general | C24: 2.6666856e+08 | D24: 2.6666856e+08

Sheet RESUMEN
A2: VILUCO S.A. — Control de Cheques
A3: =TODAY() -> 46272
A5: CHEQUES A CONFORMAR HOY
A6: Nº Cheque | B6: Fecha | C6: Importe | D6: Banco
A7: ='cheques a conf'!A2 -> 97124642 | B7: ='cheques a conf'!B2 -> 04/09/202 | C7: =IF('cheques a conf'!C2<>"",-'cheques a conf'!C2,"") -> 44935981 | D7: =IF('cheques a conf'!C2<>"",'cheques a conf'!E2,"") -> MACRO
A8: ='cheques a conf'!A3 -> 97124643 | B8: ='cheques a conf'!B3 -> 04/09/202 | C8: =IF('cheques a conf'!C3<>"",-'cheques a conf'!C3,"") -> 6617092.5 | D8: =IF('cheques a conf'!C3<>"",'cheques a conf'!E3,"") -> MACRO
A9: ='cheques a conf'!A4 -> 97124644 | B9: ='cheques a conf'!B4 -> 04/09/202 | C9: =IF('cheques a conf'!C4<>"",-'cheques a conf'!C4,"") -> 9242374.6 | D9: =IF('cheques a conf'!C4<>"",'cheques a conf'!E4,"") -> MACRO
A10: ='cheques a conf'!A5 -> 97124645 | B10: ='cheques a conf'!B5 -> 04/09/202 | C10: =IF('cheques a conf'!C5<>"",-'cheques a conf'!C5,"") -> 6838598.5 | D10: =IF('cheques a conf'!C5<>"",'cheques a conf'!E5,"") -> MACRO
A11: ='cheques a conf'!A6 -> 97124646 | B11: ='cheques a conf'!B6 -> 04/09/202 | C11: =IF('cheques a conf'!C6<>"",-'cheques a conf'!C6,"") -> 11569820 | D11: =IF('cheques a conf'!C6<>"",'cheques a conf'!E6,"") -> MACRO
A12: ='cheques a conf'!A7 -> 97124647 | B12: ='cheques a conf'!B7 -> 04/09/202 | C12: =IF('cheques a conf'!C7<>"",-'cheques a conf'!C7,"") -> 12163460 | D12: =IF('cheques a conf'!C7<>"",'cheques a conf'!E7,"") -> MACRO
A13: ='cheques a conf'!A8 -> 0 | B13: ='cheques a conf'!B8 -> 0 | C13: =IF('cheques a conf'!C8<>"",-'cheques a conf'!C8,"") | D13: =IF('cheques a conf'!C8<>"",'cheques a conf'!E8,"")
A14: ='cheques a conf'!A9 -> 0 | B14: ='cheques a conf'!B9 -> 0 | C14: =IF('cheques a conf'!C9<>"",-'cheques a conf'!C9,"") | D14: =IF('cheques a conf'!C9<>"",'cheques a conf'!E9,"")
A15: ='cheques a conf'!A10 -> 0 | B15: ='cheques a conf'!B10 -> 0 | C15: =IF('cheques a conf'!C10<>"",-'cheques a conf'!C10,"") | D15: =IF('cheques a conf'!C10<>"",'cheques a conf'!E10,"")
A16: ='cheques a conf'!A11 -> 0 | B16: ='cheques a conf'!B11 -> 0 | C16: =IF('cheques a conf'!C11<>"",-'cheques a conf'!C11,"") | D16: =IF('cheques a conf'!C11<>"",'cheques a conf'!E11,"")
A17: ='cheques a conf'!A12 -> 0 | B17: ='cheques a conf'!B12 -> 0 | C17: =IF('cheques a conf'!C12<>"",-'cheques a conf'!C12,"") | D17: =IF('cheques a conf'!C12<>"",'cheques a conf'!E12,"")
A18: ='cheques a conf'!A13 -> 0 | B18: ='cheques a conf'!B13 -> 0 | C18: =IF('cheques a conf'!C13<>"",-'cheques a conf'!C13,"") | D18: =IF('cheques a conf'!C13<>"",'cheques a conf'!E13,"")
... A26: ='cheques a conf'!A21 -> 0 | B26: ='cheques a conf'!B21 -> 0 | C26: =IF('cheques a conf'!C21<>"",-'cheques a conf'!C21,"") | D26: =IF('cheques a conf'!C21<>"",'cheques a conf'!E21,"")
A27: TOTAL A CONFORMAR | C27: =SUMIF('cheques a conf'!C2:C100,"<0",'cheques a conf'!C2:C100)*-1 -> 91367327
A29: CHEQUES A PAGAR
A30: Concepto | B30: GALICIA | C30: MACRO | D30: Total
A31: Cheques a conformar hoy | B31: =SUMIF(D7:D26,B30,C7:C26) -> 0 | C31: =SUMIF(D7:D26,C30,C7:C26) -> 91367327 | D31: =B31+C31 -> 91367327
A32: Cheques pendientes vencen esta semana | B32: {=SUMPRODUCT(('sap nuevo'!H$2:H$10000="GALICIA")*('sap nuevo'!J$2:J$10000="en periodo de pago")*('sap nuevo'!G$2:G$10000<=TODAY()-WEEKDAY(TODAY(),2)+5)*('sap nuevo'!F$2:F$10000))-B31} -> 0 | C32: {=SUMPRODUCT(('sap nuevo'!H$2:H$10000="MACRO")*('sap nuevo'!J$2:J$10000="en periodo de pago")*('sap nuevo'!G$2:G$10000<=TODAY()-WEEKDAY(TODAY(),2)+5)*('sap nuevo'!F$2:F$10000))-C31} -> 3.0703844e+08 | D32: =B32+C32 -> 3.0703844e+08
A33: Cheques que vencen en la próxima semana | B33: {=SUMPRODUCT(('sap nuevo'!H$2:H$10000="GALICIA")*('sap nuevo'!J$2:J$10000="en periodo de pago")*('sap nuevo'!G$2:G$10000>=TODAY()-WEEKDAY(TODAY(),2)+8)*('sap nuevo'!G$2:G$10000<=TODAY()-WEEKDAY(TODAY(),2)+14)*('sap nuevo'!F$2:F$10000))} -> 0 | C33: {=SUMPRODUCT(('sap nuevo'!H$2:H$10000="MACRO")*('sap nuevo'!J$2:J$10000="en periodo de pago")*('sap nuevo'!G$2:G$10000>=TODAY()-WEEKDAY(TODAY(),2)+8)*('sap nuevo'!G$2:G$10000<=TODAY()-WEEKDAY(TODAY(),2)+14)*('sap nuevo'!F$2:F$10000))} -> 0 | D33: =B33+C33 -> 0
A34: Cheques que vencen en más de 15 días | B34: {=SUMPRODUCT(('sap nuevo'!H$2:H$10000="GALICIA")*('sap nuevo'!J$2:J$10000="en periodo de pago")*('sap nuevo'!G$2:G$10000>TODAY()+15)*('sap nuevo'!F$2:F$10000))} -> 0 | C34: {=SUMPRODUCT(('sap nuevo'!H$2:H$10000="MACRO")*('sap nuevo'!J$2:J$10000="en periodo de pago")*('sap nuevo'!G$2:G$10000>=TODAY()-WEEKDAY(TODAY(),2)+15)*('sap nuevo'!F$2:F$10000))} -> 0 | D34: =B34+C34 -> 0
A35: TOTAL CHEQUES A PAGAR | B35: =B31+B32+B33+B34 -> 0 | C35: =C31+C32+C33+C34 -> 3.9840576e+08 | D35: =D31+D32+D33+D34 -> 3.9840576e+08
A37: CHEQUES CADUCADOS / FUERA DE FECHA
A38: Banco | B38: Cantidad | C38: Importe Total | D38: —
A39: GALICIA | B39: =COUNTIFS('sap nuevo'!H$2:H$10000,"GALICIA",'sap nuevo'!J$2:J$10000,"fuera de fecha",'sap nuevo'!F$2:F$10000,">0") -> 0 | C39: {=SUMPRODUCT(('sap nuevo'!H$2:H$10000="GALICIA")*('sap nuevo'!J$2:J$10000="fuera de fecha")*('sap nuevo'!F$2:F$10000>0)*('sap nuevo'!F$2:F$10000))} -> 0 | D39: —
A40: MACRO | B40: =COUNTIFS('sap nuevo'!H$2:H$10000,"MACRO",'sap nuevo'!J$2:J$10000,"fuera de fecha",'sap nuevo'!F$2:F$10000,">0") -> 8 | C40: {=SUMPRODUCT(('sap nuevo'!H$2:H$10000="MACRO")*('sap nuevo'!J$2:J$10000="fuera de fecha")*('sap nuevo'!F$2:F$10000>0)*('sap nuevo'!F$2:F$10000))} -> 46847804 | D40: —
A41: HSBC | B41: =COUNTIFS('sap nuevo'!H$2:H$10000,"HSBC",'sap nuevo'!J$2:J$10000,"fuera de fecha",'sap nuevo'!F$2:F$10000,">0") -> 1 | C41: {=SUMPRODUCT(('sap nuevo'!H$2:H$10000="HSBC")*('sap nuevo'!J$2:J$10000="fuera de fecha")*('sap nuevo'!F$2:F$10000>0)*('sap nuevo'!F$2:F$10000))} -> 112652.85 | D41: —
A42: TOTAL CADUCADOS | B42: =COUNTIFS('sap nuevo'!J$2:J$10000,"fuera de fecha",'sap nuevo'!F$2:F$10000,">0") -> 9 | C42: {=SUMPRODUCT(('sap nuevo'!J$2:J$10000="fuera de fecha")*('sap nuevo'!F$2:F$10000>0)*('sap nuevo'!F$2:F$10000))} -> 46960457

Sheet ANALISIS
B1: VILUCO S.A. — Análisis de Cheques
B2: =TODAY() -> 46272
K3: Año: | L3: 2026
B4: =" EMISIÓN MENSUAL — "&YEAR(TODAY()) -> EMISIÓN MENSUAL — 2026 | F4: RESUMEN ANUAL | J4: =" PLAZO PROM. COBRO POR MES — "&$L$3&" (días)" -> PLAZO PROM. COBRO POR MES — 2026 (días)
B5: Mes | C5: Cant. Cheques | D5: Importe Total ($) | F5: Año | G5: Cant. Cheques | H5: Importe Total ($) | J5: Mes | K5: Plazo Prom. (días) | L5: Nivel
B6: Enero | C6: {=SUMPRODUCT(('sap nuevo'!O$2:O$10000=1)*('sap nuevo'!P$2:P$10000=YEAR(TODAY()))*('sap nuevo'!F$2:F$10000>0))} -> 89 | D6: {=SUMPRODUCT(('sap nuevo'!O$2:O$10000=1)*('sap nuevo'!P$2:P$10000=YEAR(TODAY()))*('sap nuevo'!F$2:F$10000>0)*('sap nuevo'!F$2:F$10000))} -> 1.3669791e+09 | F6: =YEAR(TODAY())-2 -> 2024 | G6: {=SUMPRODUCT(('sap nuevo'!P$2:P$10000=YEAR(TODAY())-2)*('sap nuevo'!F$2:F$10000>0))} -> 0 | H6: {=SUMPRODUCT(('sap nuevo'!P$2:P$10000=YEAR(TODAY())-2)*('sap nuevo'!F$2:F$10000>0)*('sap nuevo'!F$2:F$10000))} -> 0 | J6: Enero | K6: {=IFERROR(SUMPRODUCT(('sap nuevo'!O$2:O$10000=1)*('sap nuevo'!P$2:P$10000=$L$3)*('sap nuevo'!J$2:J$10000="pagado")*('sap nuevo'!F$2:F$10000>0)*(IFERROR(DATEVALUE(_xlfn.XLOOKUP('sap nuevo'!E$2:E$10000,extracto!$C$2:$C$10000,extracto!$B$2:$B$10000))-'sap nuevo'!G$2:G$10000,0)))/SUMPRODUCT(('sap nuevo'!O$2:O$10000=1)*('sap nuevo'!P$2:P$10000=$L$3)*('sap nuevo'!J$2:J$10000="pagado")*('sap nuevo'!F$2:F$10000>0)*(ISNUMBER(DATEVALUE(_xlfn.XLOOKUP('sap nuevo'!E$2:E$10000,extracto!$C$2:$C$10000,extracto!$B$2:$B$10000))))),0)} -> 3.2413793 | L6: =IF(K6=0,"—",IF(K6>6,"▲ Alto",IF(K6>4,"● Medio","▼ Normal"))) -> ▼ Normal
B7: Febrero | C7: {=SUMPRODUCT(('sap nuevo'!O$2:O$10000=2)*('sap nuevo'!P$2:P$10000=YEAR(TODAY()))*('sap nuevo'!F$2:F$10000>0))} -> 96 | D7: {=SUMPRODUCT(('sap nuevo'!O$2:O$10000=2)*('sap nuevo'!P$2:P$10000=YEAR(TODAY()))*('sap nuevo'!F$2:F$10000>0)*('sap nuevo'!F$2:F$10000))} -> 9.5349074e+08 | F7: =YEAR(TODAY())-1 -> 2025 | G7: {=SUMPRODUCT(('sap nuevo'!P$2:P$10000=YEAR(TODAY())-1)*('sap nuevo'!F$2:F$10000>0))} -> 928 | H7: {=SUMPRODUCT(('sap nuevo'!P$2:P$10000=YEAR(TODAY())-1)*('sap nuevo'!F$2:F$10000>0)*('sap nuevo'!F$2:F$10000))} -> 9.1359325e+09 | J7: Febrero | K7: {=IFERROR(SUMPRODUCT(('sap nuevo'!O$2:O$10000=2)*('sap nuevo'!P$2:P$10000=$L$3)*('sap nuevo'!J$2:J$10000="pagado")*('sap nuevo'!F$2:F$10000>0)*(IFERROR(DATEVALUE(_xlfn.XLOOKUP('sap nuevo'!E$2:E$10000,extracto!$C$2:$C$10000,extracto!$B$2:$B$10000))-'sap nuevo'!G$2:G$10000,0)))/SUMPRODUCT(('sap nuevo'!O$2:O$10000=2)*('sap nuevo'!P$2:P$10000=$L$3)*('sap nuevo'!J$2:J$10000="pagado")*('sap nuevo'!F$2:F$10000>0)*(ISNUMBER(DATEVALUE(_xlfn.XLOOKUP('sap nuevo'!E$2:E$10000,extracto!$C$2:$C$10000,extracto!$B$2:$B$10000))))),0)} -> 5.1354167 | L7: =IF(K7=0,"—",IF(K7>6,"▲ Alto",IF(K7>4,"● Medio","▼ Normal"))) -> ● Medio
B8: Marzo | C8: {=SUMPRODUCT(('sap nuevo'!O$2:O$10000=3)*('sap nuevo'!P$2:P$10000=YEAR(TODAY()))*('sap nuevo'!F$2:F$10000>0))} -> 49 | D8: {=SUMPRODUCT(('sap nuevo'!O$2:O$10000=3)*('sap nuevo'!P$2:P$10000=YEAR(TODAY()))*('sap nuevo'!F$2:F$10000>0)*('sap nuevo'!F$2:F$10000))} -> 7.5390708e+08 | F8: =YEAR(TODAY()) -> 2026 | G8: {=SUMPRODUCT(('sap nuevo'!P$2:P$10000=YEAR(TODAY()))*('sap nuevo'!F$2:F$10000>0))} -> 543 | H8: {=SUMPRODUCT(('sap nuevo'!P$2:P$10000=YEAR(TODAY()))*('sap nuevo'!F$2:F$10000>0)*('sap nuevo'!F$2:F$10000))} -> 8.8921435e+09 | J8: Marzo | K8: {=IFERROR(SUMPRODUCT(('sap nuevo'!O$2:O$10000=3)*('sap nuevo'!P$2:P$10000=$L$3)*('sap nuevo'!J$2:J$10000="pagado")*('sap nuevo'!F$2:F$10000>0)*(IFERROR(DATEVALUE(_xlfn.XLOOKUP('sap nuevo'!E$2:E$10000,extracto!$C$2:$C$10000,extracto!$B$2:$B$10000))-'sap nuevo'!G$2:G$10000,0)))/SUMPRODUCT(('sap nuevo'!O$2:O$10000=3)*('sap nuevo'!P$2:P$10000=$L$3)*('sap nuevo'!J$2:J$10000="pagado")*('sap nuevo'!F$2:F$10000>0)*(ISNUMBER(DATEVALUE(_xlfn.XLOOKUP('sap nuevo'!E$2:E$10000,extracto!$C$2:$C$10000,extracto!$B$2:$B$10000))))),0)} -> 2.4545455 | L8: =IF(K8=0,"—",IF(K8>6,"▲ Alto",IF(K8>4,"● Medio","▼ Normal"))) -> ▼ Normal
B9: Abril | C9: {=SUMPRODUCT(('sap nuevo'!O$2:O$10000=4)*('sap nuevo'!P$2:P$10000=YEAR(TODAY()))*('sap nuevo'!F$2:F$10000>0))} -> 44 | D9: {=SUMPRODUCT(('sap nuevo'!O$2:O$10000=4)*('sap nuevo'!P$2:P$10000=YEAR(TODAY()))*('sap nuevo'!F$2:F$10000>0)*('sap nuevo'!F$2:F$10000))} -> 6.1032794e+08 | F9: TOTAL | G9: =SUM(G6:G8) -> 1471 | H9: =SUM(H6:H8) -> 1.8028076e+10 | J9: Abril | K9: {=IFERROR(SUMPRODUCT(('sap nuevo'!O$2:O$10000=4)*('sap nuevo'!P$2:P$10000=$L$3)*('sap nuevo'!J$2:J$10000="pagado")*('sap nuevo'!F$2:F$10000>0)*(IFERROR(DATEVALUE(_xlfn.XLOOKUP('sap nuevo'!E$2:E$10000,extracto!$C$2:$C$10000,extracto!$B$2:$B$10000))-'sap nuevo'!G$2:G$10000,0)))/SUMPRODUCT(('sap nuevo'!O$2:O$10000=4)*('sap nuevo'!P$2:P$10000=$L$3)*('sap nuevo'!J$2:J$10000="pagado")*('sap nuevo'!F$2:F$10000>0)*(ISNUMBER(DATEVALUE(_xlfn.XLOOKUP('sap nuevo'!E$2:E$10000,extracto!$C$2:$C$10000,extracto!$B$2:$B$10000))))),0)} -> 0 | L9: =IF(K9=0,"—",IF(K9>6,"▲ Alto",IF(K9>4,"● Medio","▼ Normal"))) -> —
B10: Mayo | C10: {=SUMPRODUCT(('sap nuevo'!O$2:O$10000=5)*('sap nuevo'!P$2:P$10000=YEAR(TODAY()))*('sap nuevo'!F$2:F$10000>0))} -> 40 | D10: {=SUMPRODUCT(('sap nuevo'!O$2:O$10000=5)*('sap nuevo'!P$2:P$10000=YEAR(TODAY()))*('sap nuevo'!F$2:F$10000>0)*('sap nuevo'!F$2:F$10000))} -> 6.8352544e+08 | J10: Mayo | K10: {=IFERROR(SUMPRODUCT(('sap nuevo'!O$2:O$10000=5)*('sap nuevo'!P$2:P$10000=$L$3)*('sap nuevo'!J$2:J$10000="pagado")*('sap nuevo'!F$2:F$10000>0)*(IFERROR(DATEVALUE(_xlfn.XLOOKUP('sap nuevo'!E$2:E$10000,extracto!$C$2:$C$10000,extracto!$B$2:$B$10000))-'sap nuevo'!G$2:G$10000,0)))/SUMPRODUCT(('sap nuevo'!O$2:O$10000=5)*('sap nuevo'!P$2:P$10000=$L$3)*('sap nuevo'!J$2:J$10000="pagado")*('sap nuevo'!F$2:F$10000>0)*(ISNUMBER(DATEVALUE(_xlfn.XLOOKUP('sap nuevo'!E$2:E$10000,extracto!$C$2:$C$10000,extracto!$B$2:$B$10000))))),0)} -> 0 | L10: =IF(K10=0,"—",IF(K10>6,"▲ Alto",IF(K10>4,"● Medio","▼ Normal"))) -> —
B11: Junio | C11: {=SUMPRODUCT(('sap nuevo'!O$2:O$10000=6)*('sap nuevo'!P$2:P$10000=YEAR(TODAY()))*('sap nuevo'!F$2:F$10000>0))} -> 63 | D11: {=SUMPRODUCT(('sap nuevo'!O$2:O$10000=6)*('sap nuevo'!P$2:P$10000=YEAR(TODAY()))*('sap nuevo'!F$2:F$10000>0)*('sap nuevo'!F$2:F$10000))} -> 1.4082389e+09 | F11: DISTRIBUCIÓN POR BANCO | J11: Junio | K11: {=IFERROR(SUMPRODUCT(('sap nuevo'!O$2:O$10000=6)*('sap nuevo'!P$2:P$10000=$L$3)*('sap nuevo'!J$2:J$10000="pagado")*('sap nuevo'!F$2:F$10000>0)*(IFERROR(DATEVALUE(_xlfn.XLOOKUP('sap nuevo'!E$2:E$10000,extracto!$C$2:$C$10000,extracto!$B$2:$B$10000))-'sap nuevo'!G$2:G$10000,0)))/SUMPRODUCT(('sap nuevo'!O$2:O$10000=6)*('sap nuevo'!P$2:P$10000=$L$3)*('sap nuevo'!J$2:J$10000="pagado")*('sap nuevo'!F$2:F$10000>0)*(ISNUMBER(DATEVALUE(_xlfn.XLOOKUP('sap nuevo'!E$2:E$10000,extracto!$C$2:$C$10000,extracto!$B$2:$B$10000))))),0)} -> 4.4035088 | L11: =IF(K11=0,"—",IF(K11>6,"▲ Alto",IF(K11>4,"● Medio","▼ Normal"))) -> ● Medio
B12: Julio | C12: {=SUMPRODUCT(('sap nuevo'!O$2:O$10000=7)*('sap nuevo'!P$2:P$10000=YEAR(TODAY()))*('sap nuevo'!F$2:F$10000>0))} -> 41 | D12: {=SUMPRODUCT(('sap nuevo'!O$2:O$10000=7)*('sap nuevo'!P$2:P$10000=YEAR(TODAY()))*('sap nuevo'!F$2:F$10000>0)*('sap nuevo'!F$2:F$10000))} -> 5.2014362e+08 | F12: Banco | G12: Cant. Cheques | H12: Importe Total ($) | J12: Julio | K12: {=IFERROR(SUMPRODUCT(('sap nuevo'!O$2:O$10000=7)*('sap nuevo'!P$2:P$10000=$L$3)*('sap nuevo'!J$2:J$10000="pagado")*('sap nuevo'!F$2:F$10000>0)*(IFERROR(DATEVALUE(_xlfn.XLOOKUP('sap nuevo'!E$2:E$10000,extracto!$C$2:$C$10000,extracto!$B$2:$B$10000))-'sap nuevo'!G$2:G$10000,0)))/SUMPRODUCT(('sap nuevo'!O$2:O$10000=7)*('sap nuevo'!P$2:P$10000=$L$3)*('sap nuevo'!J$2:J$10000="pagado")*('sap nuevo'!F$2:F$10000>0)*(ISNUMBER(DATEVALUE(_xlfn.XLOOKUP('sap nuevo'!E$2:E$10000,extracto!$C$2:$C$10000,extracto!$B$2:$B$10000))))),0)} -> 3.1707317 | L12: =IF(K12=0,"—",IF(K12>6,"▲ Alto",IF(K12>4,"● Medio","▼ Normal"))) -> ▼ Normal
B13: Agosto | C13: {=SUMPRODUCT(('sap nuevo'!O$2:O$10000=8)*('sap nuevo'!P$2:P$10000=YEAR(TODAY()))*('sap nuevo'!F$2:F$10000>0))} -> 83 | D13: {=SUMPRODUCT(('sap nuevo'!O$2:O$10000=8)*('sap nuevo'!P$2:P$10000=YEAR(TODAY()))*('sap nuevo'!F$2:F$10000>0)*('sap nuevo'!F$2:F$10000))} -> 1.9618553e+09 | F13: GALICIA | G13: =COUNTIFS('sap nuevo'!H$2:H$10000,"GALICIA",'sap nuevo'!F$2:F$10000,">0") -> 0 | H13: =SUMIF('sap nuevo'!H$2:H$10000,"GALICIA",'sap nuevo'!F$2:F$10000) -> 0 | J13: Agosto | K13: {=IFERROR(SUMPRODUCT(('sap nuevo'!O$2:O$10000=8)*('sap nuevo'!P$2:P$10000=$L$3)*('sap nuevo'!J$2:J$10000="pagado")*('sap nuevo'!F$2:F$10000>0)*(IFERROR(DATEVALUE(_xlfn.XLOOKUP('sap nuevo'!E$2:E$10000,extracto!$C$2:$C$10000,extracto!$B$2:$B$10000))-'sap nuevo'!G$2:G$10000,0)))/SUMPRODUCT(('sap nuevo'!O$2:O$10000=8)*('sap nuevo'!P$2:P$10000=$L$3)*('sap nuevo'!J$2:J$10000="pagado")*('sap nuevo'!F$2:F$10000>0)*(ISNUMBER(DATEVALUE(_xlfn.XLOOKUP('sap nuevo'!E$2:E$10000,extracto!$C$2:$C$10000,extracto!$B$2:$B$10000))))),0)} -> 2.4634146 | L13: =IF(K13=0,"—",IF(K13>6,"▲ Alto",IF(K13>4,"● Medio","▼ Normal"))) -> ▼ Normal
B14: Septiembre | C14: {=SUMPRODUCT(('sap nuevo'!O$2:O$10000=9)*('sap nuevo'!P$2:P$10000=YEAR(TODAY()))*('sap nuevo'!F$2:F$10000>0))} -> 38 | D14: {=SUMPRODUCT(('sap nuevo'!O$2:O$10000=9)*('sap nuevo'!P$2:P$10000=YEAR(TODAY()))*('sap nuevo'!F$2:F$10000>0)*('sap nuevo'!F$2:F$10000))} -> 6.3367532e+08 | F14: MACRO | G14: =COUNTIFS('sap nuevo'!H$2:H$10000,"MACRO",'sap nuevo'!F$2:F$10000,">0") -> 1276 | H14: =SUMIF('sap nuevo'!H$2:H$10000,"MACRO",'sap nuevo'!F$2:F$10000) -> 1.6848872e+10 | J14: Septiembre | K14: {=IFERROR(SUMPRODUCT(('sap nuevo'!O$2:O$10000=9)*('sap nuevo'!P$2:P$10000=$L$3)*('sap nuevo'!J$2:J$10000="pagado")*('sap nuevo'!F$2:F$10000>0)*(IFERROR(DATEVALUE(_xlfn.XLOOKUP('sap nuevo'!E$2:E$10000,extracto!$C$2:$C$10000,extracto!$B$2:$B$10000))-'sap nuevo'!G$2:G$10000,0)))/SUMPRODUCT(('sap nuevo'!O$2:O$10000=9)*('sap nuevo'!P$2:P$10000=$L$3)*('sap nuevo'!J$2:J$10000="pagado")*('sap nuevo'!F$2:F$10000>0)*(ISNUMBER(DATEVALUE(_xlfn.XLOOKUP('sap nuevo'!E$2:E$10000,extracto!$C$2:$C$10000,extracto!$B$2:$B$10000))))),0)} -> 0.95238095 | L14: =IF(K14=0,"—",IF(K14>6,"▲ Alto",IF(K14>4,"● Medio","▼ Normal"))) -> ▼ Normal
