Workbook

Sheet sap nuevo
A1: Nº doc. | B1: Fecha doc. | C1: Importe en ML | D1: Usuario | E1: numero de cheque | F1: importe | G1: Fe.valor | H1: Banco | I1: pagado | J1: estado | K1: estado dos | L1: estado tres | M1: en cartera | N1: semana | O1: mes | P1: AÑO | Q1: periodo | R1: semana actual | T1: FECHA DE CORTE | U1: HOY | V1: =+IF(U1="HOY",Y1,AA1) -> 46272 | X1: HOY | Y1: =+TODAY() -> 46272 | Z1: CIERRE | AA1: 44629
A2: 3000000030 | B2: 45659 | C2: 0 | D2: Anulado | E2: 91002228 | F2: 0 | G2: 45659 | H2: MACRO | I2: =IFERROR(IF(VLOOKUP(E2,extracto!C:C,1,FALSE)=E2,"pagado","no pagado"),"no pagado") -> no pagado | J2: =IF(I2="pagado","pagado",IF(G2<$V$1-30,"fuera de fecha","en periodo de pago")) -> fuera de fecha | K2: =+IF(B2>$V$1,"excluir",IF(J2="en periodo de pago",IF($V$1>G2,"a pagar","proximo a vencer"),"excluir")) -> excluir | L2: =+IF(K2="proximo a vencer",IF($V$1+5>G2,"para la semana","no semana"),"no semana") -> no semana | M2: =IFERROR(VLOOKUP(E2,'cheques a conf'!A:D,4,FALSE),"no clearing") -> no clearing | N2: =+WEEKNUM(G2,2) -> 1 | O2: =+MONTH(G2) -> 1 | P2: =+YEAR(G2) -> 2025
A3: 3000000031 | B3: 45659 | C3: 4656543.4 | D3: HYDRASER SA ROSARIO 12 | E3: 91002229 | F3: 4656543.4 | G3: 45663 | H3: MACRO | I3: =IFERROR(IF(VLOOKUP(E3,extracto!C:C,1,FALSE)=E3,"pagado","no pagado"),"no pagado") -> pagado | J3: =IF(I3="pagado","pagado",IF(G3<$V$1-30,"fuera de fecha","en periodo de pago")) -> pagado | K3: =+IF(B3>$V$1,"excluir",IF(J3="en periodo de pago",IF($V$1>G3,"a pagar","proximo a vencer"),"excluir")) -> excluir | L3: =+IF(K3="proximo a vencer",IF($V$1+5>G3,"para la semana","no semana"),"no semana") -> no semana | M3: =IFERROR(VLOOKUP(E3,'cheques a conf'!A:D,4,FALSE),"no clearing") -> no clearing | N3: =+WEEKNUM(G3,2) -> 2 | O3: =+MONTH(G3) -> 1 | P3: =+YEAR(G3) -> 2025
A4: 3000000032 | B4: 45659 | C4: 4183758.4 | D4: LOBO BENICIO MARTIN ALDERETES 14 | E4: 91002230 | F4: 4183758.4 | G4: 45663 | H4: MACRO | I4: =IFERROR(IF(VLOOKUP(E4,extracto!C:C,1,FALSE)=E4,"pagado","no pagado"),"no pagado") -> pagado | J4: =IF(I4="pagado","pagado",IF(G4<$V$1-30,"fuera de fecha","en periodo de pago")) -> pagado | K4: =+IF(B4>$V$1,"excluir",IF(J4="en periodo de pago",IF($V$1>G4,"a pagar","proximo a vencer"),"excluir")) -> excluir | L4: =+IF(K4="proximo a vencer",IF($V$1+5>G4,"para la semana","no semana"),"no semana") -> no semana | M4: =IFERROR(VLOOKUP(E4,'cheques a conf'!A:D,4,FALSE),"no clearing") -> no clearing | N4: =+WEEKNUM(G4,2) -> 2 | O4: =+MONTH(G4) -> 1 | P4: =+YEAR(G4) -> 2025
A5: 3000000033 | B5: 45659 | C5: 9873403.4 | D5: PABLO Y FERNANDO TACCHELLA S.RSAN MIGUEL DE TUCUMAN 14 | E5: 91002231 | F5: 9873403.4 | G5: 45664 | H5: MACRO | I5: =IFERROR(IF(VLOOKUP(E5,extracto!C:C,1,FALSE)=E5,"pagado","no pagado"),"no pagado") -> pagado | J5: =IF(I5="pagado","pagado",IF(G5<$V$1-30,"fuera de fecha","en periodo de pago")) -> pagado | K5: =+IF(B5>$V$1,"excluir",IF(J5="en periodo de pago",IF($V$1>G5,"a pagar","proximo a vencer"),"excluir")) -> excluir | L5: =+IF(K5="proximo a vencer",IF($V$1+5>G5,"para la semana","no semana"),"no semana") -> no semana | M5: =IFERROR(VLOOKUP(E5,'cheques a conf'!A:D,4,FALSE),"no clearing") -> no clearing | N5: =+WEEKNUM(G5,2) -> 2 | O5: =+MONTH(G5) -> 1 | P5: =+YEAR(G5) -> 2025
A6: 3000000034 | B6: 45659 | C6: 6665838.3 | D6: Servicom Group S.A. CAPITAL FEDERAL 00 | E6: 91002232 | F6: 6665838.3 | G6: 45664 | H6: MACRO | I6: =IFERROR(IF(VLOOKUP(E6,extracto!C:C,1,FALSE)=E6,"pagado","no pagado"),"no pagado") -> pagado | J6: =IF(I6="pagado","pagado",IF(G6<$V$1-30,"fuera de fecha","en periodo de pago")) -> pagado | K6: =+IF(B6>$V$1,"excluir",IF(J6="en periodo de pago",IF($V$1>G6,"a pagar","proximo a vencer"),"excluir")) -> excluir | L6: =+IF(K6="proximo a vencer",IF($V$1+5>G6,"para la semana","no semana"),"no semana") -> no semana | M6: =IFERROR(VLOOKUP(E6,'cheques a conf'!A:D,4,FALSE),"no clearing") -> no clearing | N6: =+WEEKNUM(G6,2) -> 2 | O6: =+MONTH(G6) -> 1 | P6: =+YEAR(G6) -> 2025
A7: 3000000083 | B7: 45663 | C7: 6715811.8 | D7: MERCATOR TRANSPORT ARGENTINA SBUENOS AIRES 01 | E7: 2927344 | F7: 6715811.8 | G7: 45663 | H7: HSBC | I7: =IFERROR(IF(VLOOKUP(E7,extracto!C:C,1,FALSE)=E7,"pagado","no pagado"),"no pagado") -> pagado | J7: =IF(I7="pagado","pagado",IF(G7<$V$1-30,"fuera de fecha","en periodo de pago")) -> pagado | K7: =+IF(B7>$V$1,"excluir",IF(J7="en periodo de pago",IF($V$1>G7,"a pagar","proximo a vencer"),"excluir")) -> excluir | L7: =+IF(K7="proximo a vencer",IF($V$1+5>G7,"para la semana","no semana"),"no semana") -> no semana | M7: =IFERROR(VLOOKUP(E7,'cheques a conf'!A:D,4,FALSE),"no clearing") -> no clearing | N7: =+WEEKNUM(G7,2) -> 2 | O7: =+MONTH(G7) -> 1 | P7: =+YEAR(G7) -> 2025
A8: 3000000109 | B8: 45664 | C8: 37609624 | D8: Greif Argentina SA Tigre 01 | E8: 2927345 | F8: 37609624 | G8: 45664 | H8: HSBC | I8: =IFERROR(IF(VLOOKUP(E8,extracto!C:C,1,FALSE)=E8,"pagado","no pagado"),"no pagado") -> pagado | J8: =IF(I8="pagado","pagado",IF(G8<$V$1-30,"fuera de fecha","en periodo de pago")) -> pagado | K8: =+IF(B8>$V$1,"excluir",IF(J8="en periodo de pago",IF($V$1>G8,"a pagar","proximo a vencer"),"excluir")) -> excluir | L8: =+IF(K8="proximo a vencer",IF($V$1+5>G8,"para la semana","no semana"),"no semana") -> no semana | M8: =IFERROR(VLOOKUP(E8,'cheques a conf'!A:D,4,FALSE),"no clearing") -> no clearing | N8: =+WEEKNUM(G8,2) -> 2 | O8: =+MONTH(G8) -> 1 | P8: =+YEAR(G8) -> 2025
A9: 3000000110 | B9: 45664 | C9: 18230418 | D9: MONTEROS LEMON SAS TAFI VIEJO 14 | E9: 2927346 | F9: 18230418 | G9: 45664 | H9: HSBC | I9: =IFERROR(IF(VLOOKUP(E9,extracto!C:C,1,FALSE)=E9,"pagado","no pagado"),"no pagado") -> pagado | J9: =IF(I9="pagado","pagado",IF(G9<$V$1-30,"fuera de fecha","en periodo de pago")) -> pagado | K9: =+IF(B9>$V$1,"excluir",IF(J9="en periodo de pago",IF($V$1>G9,"a pagar","proximo a vencer"),"excluir")) -> excluir | L9: =+IF(K9="proximo a vencer",IF($V$1+5>G9,"para la semana","no semana"),"no semana") -> no semana | M9: =IFERROR(VLOOKUP(E9,'cheques a conf'!A:D,4,FALSE),"no clearing") -> no clearing | N9: =+WEEKNUM(G9,2) -> 2 | O9: =+MONTH(G9) -> 1 | P9: =+YEAR(G9) -> 2025
A10: 3000000149 | B10: 45665 | C10: 20000000 | D10: BONSUR SA CAPITAL FEDERAL 00 | E10: 91002234 | F10: 20000000 | G10: 45670 | H10: MACRO | I10: =IFERROR(IF(VLOOKUP(E10,extracto!C:C,1,FALSE)=E10,"pagado","no pagado"),"no pagado") -> pagado | J10: =IF(I10="pagado","pagado",IF(G10<$V$1-30,"fuera de fecha","en periodo de pago")) -> pagado | K10: =+IF(B10>$V$1,"excluir",IF(J10="en periodo de pago",IF($V$1>G10,"a pagar","proximo a vencer"),"excluir")) -> excluir | L10: =+IF(K10="proximo a vencer",IF($V$1+5>G10,"para la semana","no semana"),"no semana") -> no semana | M10: =IFERROR(VLOOKUP(E10,'cheques a conf'!A:D,4,FALSE),"no clearing") -> no clearing | N10: =+WEEKNUM(G10,2) -> 3 | O10: =+MONTH(G10) -> 1 | P10: =+YEAR(G10) -> 2025
A11: 3000000149 | B11: 45665 | C11: 19850368 | D11: BONSUR SA CAPITAL FEDERAL 00 | E11: 91002235 | F11: 19850368 | G11: 45671 | H11: MACRO | I11: =IFERROR(IF(VLOOKUP(E11,extracto!C:C,1,FALSE)=E11,"pagado","no pagado"),"no pagado") -> pagado | J11: =IF(I11="pagado","pagado",IF(G11<$V$1-30,"fuera de fecha","en periodo de pago")) -> pagado | K11: =+IF(B11>$V$1,"excluir",IF(J11="en periodo de pago",IF($V$1>G11,"a pagar","proximo a vencer"),"excluir")) -> excluir | L11: =+IF(K11="proximo a vencer",IF($V$1+5>G11,"para la semana","no semana"),"no semana") -> no semana | M11: =IFERROR(VLOOKUP(E11,'cheques a conf'!A:D,4,FALSE),"no clearing") -> no clearing | N11: =+WEEKNUM(G11,2) -> 3 | O11: =+MONTH(G11) -> 1 | P11: =+YEAR(G11) -> 2025
A12: 3000000148 | B12: 45665 | C12: 22860153 | D12: Terminal 4 S.A. Puerto Nuevo 01 | E12: 91002233 | F12: 22860153 | G12: 45667 | H12: MACRO | I12: =IFERROR(IF(VLOOKUP(E12,extracto!C:C,1,FALSE)=E12,"pagado","no pagado"),"no pagado") -> pagado | J12: =IF(I12="pagado","pagado",IF(G12<$V$1-30,"fuera de fecha","en periodo de pago")) -> pagado | K12: =+IF(B12>$V$1,"excluir",IF(J12="en periodo de pago",IF($V$1>G12,"a pagar","proximo a vencer"),"excluir")) -> excluir | L12: =+IF(K12="proximo a vencer",IF($V$1+5>G12,"para la semana","no semana"),"no semana") -> no semana | M12: =IFERROR(VLOOKUP(E12,'cheques a conf'!A:D,4,FALSE),"no clearing") -> no clearing | N12: =+WEEKNUM(G12,2) -> 2 | O12: =+MONTH(G12) -> 1 | P12: =+YEAR(G12) -> 2025
A13: 3000000150 | B13: 45666 | C13: 2000000 | D13: . Tucumán | E13: 94326781 | F13: 2000000 | G13: 45666 | H13: HSBC | I13: =IFERROR(IF(VLOOKUP(E13,extracto!C:C,1,FALSE)=E13,"pagado","no pagado"),"no pagado") -> pagado | J13: =IF(I13="pagado","pagado",IF(G13<$V$1-30,"fuera de fecha","en periodo de pago")) -> pagado | K13: =+IF(B13>$V$1,"excluir",IF(J13="en periodo de pago",IF($V$1>G13,"a pagar","proximo a vencer"),"excluir")) -> excluir | L13: =+IF(K13="proximo a vencer",IF($V$1+5>G13,"para la semana","no semana"),"no semana") -> no semana | M13: =IFERROR(VLOOKUP(E13,'cheques a conf'!A:D,4,FALSE),"no clearing") -> no clearing | N13: =+WEEKNUM(G13,2) -> 2 | O13: =+MONTH(G13) -> 1 | P13: =+YEAR(G13) -> 2025
... A2460: 3000005643 | B2460: 46267 | C2460: 17393857 | D2460: JACQUET NORBERTO SALVADOR SAN JOSE 05 | E2460: 91003561 | F2460: 17393857 | G2460: 46272 | H2460: MACRO | I2460: =IFERROR(IF(VLOOKUP(E2460,extracto!C:C,1,FALSE)=E2460,"pagado","no pagado"),"no pagado") -> no pagado | J2460: =IF(I2460="pagado","pagado",IF(G2460<$V$1-30,"fuera de fecha","en periodo de pago")) -> en periodo de pago | K2460: =+IF(B2460>$V$1,"excluir",IF(J2460="en periodo de pago",IF($V$1>G2460,"a pagar","proximo a vencer"),"excluir")) -> proximo a vencer | L2460: =+IF(K2460="proximo a vencer",IF($V$1+5>G2460,"para la semana","no semana"),"no semana") -> para la semana | M2460: =IFERROR(VLOOKUP(E2460,'cheques a conf'!A:D,4,FALSE),"no clearing") -> no clearing | N2460: =+WEEKNUM(G2460,2) -> 37 | O2460: =+MONTH(G2460) -> 9 | P2460: =+YEAR(G2460) -> 2026
H2461: MACRO | I2461: =IFERROR(IF(VLOOKUP(E2461,extracto!C:C,1,FALSE)=E2461,"pagado","no pagado"),"no pagado") -> no pagado | J2461: =IF(I2461="pagado","pagado",IF(G2461<$V$1-30,"fuera de fecha","en periodo de pago")) -> fuera de fecha | K2461: =+IF(B2461>$V$1,"excluir",IF(J2461="en periodo de pago",IF($V$1>G2461,"a pagar","proximo a vencer"),"excluir")) -> excluir | L2461: =+IF(K2461="proximo a vencer",IF($V$1+5>G2461,"para la semana","no semana"),"no semana") -> no semana | M2461: =IFERROR(VLOOKUP(E2461,'cheques a conf'!A:D,4,FALSE),"no clearing") -> no clearing | N2461: =+WEEKNUM(G2461,2) -> 1 | O2461: =+MONTH(G2461) -> 1 | P2461: =+YEAR(G2461) -> 1900
I2462: =IFERROR(IF(VLOOKUP(E2462,extracto!C:C,1,FALSE)=E2462,"pagado","no pagado"),"no pagado") -> no pagado | J2462: =IF(I2462="pagado","pagado",IF(G2462<$V$1-30,"fuera de fecha","en periodo de pago")) -> fuera de fecha | K2462: =+IF(B2462>$V$1,"excluir",IF(J2462="en periodo de pago",IF($V$1>G2462,"a pagar","proximo a vencer"),"excluir")) -> excluir | L2462: =+IF(K2462="proximo a vencer",IF($V$1+5>G2462,"para la semana","no semana"),"no semana") -> no semana | M2462: =IFERROR(VLOOKUP(E2462,'cheques a conf'!A:D,4,FALSE),"no clearing") -> no clearing | N2462: =+WEEKNUM(G2462,2) -> 1 | O2462: =+MONTH(G2462) -> 1 | P2462: =+YEAR(G2462) -> 1900

Sheet extracto
A1: Concepto/Cod,Op, | B1: Fecha | C1: Comprobante | D1: Sucursal | E1: Importe | F1: Descripción | G1: Cod,Op,Bco, | I1: AÑO | J1: MES | M1: 1 | N1: 2 | O1: 3 | P1: 4 | Q1: 5 | R1: 6 | S1: 7 | T1: 8 | U1: 9 | V1: 10 | W1: 11 | X1: 12
A2: CH/RECIB48 | B2: 02/01/2025 | C2: 2927339 | D2: 52 | E2: -30000000 | F2: CHEQUE 48 HORAS | G2: 2 | H2: =+IF(B2>'sap nuevo'!$V$1,"cargar",IF(C2="","cargar","pagado")) -> cargar | I2: =+YEAR(B2) -> 2025 | J2: =+MONTH(B2) -> 1
A3: CH/RECIB48 | B3: 02/01/2025 | C3: 94326773 | D3: 52 | E3: -21000000 | F3: CHEQUE 48 HORAS | G3: 2 | H3: =+IF(B3>'sap nuevo'!$V$1,"cargar",IF(C3="","cargar","pagado")) -> cargar | I3: =+YEAR(B3) -> 2025 | J3: =+MONTH(B3) -> 1
A4: CH/RECIB48 | B4: 30/12/2024 | C4: 91002225 | D4: 140 | E4: -20000000 | F4: CHEQUE P/CAMARA | G4: 0 | H4: =+IF(B4>'sap nuevo'!$V$1,"cargar",IF(C4="","cargar","pagado")) -> cargar | I4: =+YEAR(B4) -> 2024 | J4: =+MONTH(B4) -> 12
A5: CH/RECIB48 | B5: 30/12/2024 | C5: 91002223 | D5: 140 | E5: -13728008 | F5: CHEQUE P/CAMARA | G5: 0 | H5: =+IF(B5>'sap nuevo'!$V$1,"cargar",IF(C5="","cargar","pagado")) -> cargar | I5: =+YEAR(B5) -> 2024 | J5: =+MONTH(B5) -> 12
A6: CH/RECIB48 | B6: 30/12/2024 | C6: 91002224 | D6: 140 | E6: -10094700 | F6: CHEQUE P/CAMARA | G6: 0 | H6: =+IF(B6>'sap nuevo'!$V$1,"cargar",IF(C6="","cargar","pagado")) -> cargar | I6: =+YEAR(B6) -> 2024 | J6: =+MONTH(B6) -> 12
A7: CH/RECIB48 | B7: 30/12/2024 | C7: 91002227 | D7: 140 | E7: -8957715.9 | F7: CHEQUE P/CAMARA | G7: 0 | H7: =+IF(B7>'sap nuevo'!$V$1,"cargar",IF(C7="","cargar","pagado")) -> cargar | I7: =+YEAR(B7) -> 2024 | J7: =+MONTH(B7) -> 12
A8: CH/PAG | B8: 30/12/2024 | C8: 91002221 | D8: 140 | E8: -8617859.3 | F8: CHEQUE CANJE INTERNO | G8: 0 | H8: =+IF(B8>'sap nuevo'!$V$1,"cargar",IF(C8="","cargar","pagado")) -> cargar | I8: =+YEAR(B8) -> 2024 | J8: =+MONTH(B8) -> 12
A9: CH/RECIB48 | B9: 30/12/2024 | C9: 91002222 | D9: 140 | E9: -6807063.8 | F9: CHEQUE P/CAMARA | G9: 0 | H9: =+IF(B9>'sap nuevo'!$V$1,"cargar",IF(C9="","cargar","pagado")) -> cargar | I9: =+YEAR(B9) -> 2024 | J9: =+MONTH(B9) -> 12
A10: CH/RECIB48 | B10: 30/12/2024 | C10: 91002219 | D10: 140 | E10: -5744691.2 | F10: CHEQUE P/CAMARA | G10: 0 | H10: =+IF(B10>'sap nuevo'!$V$1,"cargar",IF(C10="","cargar","pagado")) -> cargar | I10: =+YEAR(B10) -> 2024 | J10: =+MONTH(B10) -> 12
A11: CH/RECIB48 | B11: 30/12/2024 | C11: 91002220 | D11: 140 | E11: -5137431.2 | F11: CHEQUE P/CAMARA | G11: 0 | H11: =+IF(B11>'sap nuevo'!$V$1,"cargar",IF(C11="","cargar","pagado")) -> cargar | I11: =+YEAR(B11) -> 2024 | J11: =+MONTH(B11) -> 12
A12: CH/RECIB48 | B12: 03/01/2025 | C12: 2927340 | D12: 52 | E12: -28938605 | F12: CHEQUE 48 HORAS | G12: 2 | H12: =+IF(B12>'sap nuevo'!$V$1,"cargar",IF(C12="","cargar","pagado")) -> cargar | I12: =+YEAR(B12) -> 2025 | J12: =+MONTH(B12) -> 1
A13: CH/RECIB48 | B13: 03/01/2025 | C13: 94326775 | D13: 52 | E13: -2430186.2 | F13: CHEQUE 48 HORAS | G13: 2 | H13: =+IF(B13>'sap nuevo'!$V$1,"cargar",IF(C13="","cargar","pagado")) -> cargar | I13: =+YEAR(B13) -> 2025 | J13: =+MONTH(B13) -> 1
... A1688: CH/PAG | B1688: 25/02/2026 | C1688: 40273010 | D1688: 140 | E1688: -21631711 | F1688: CHEQUE CANJE INTERNO | G1688: 0 | H1688: =+IF(B1688>'sap nuevo'!$V$1,"cargar",IF(C1688="","cargar","pagado")) -> cargar | I1688: =+YEAR(B1688) -> 2026 | J1688: =+MONTH(B1688) -> 2
A1689: CH.PROPIO | B1689: 46079 | C1689: 2042 | D1689: 9999 | E1689: 172055660 | F1689: ECHEQGAL 2042 | G1689: 3520 | H1689: =+IF(B1689>'sap nuevo'!$V$1,"cargar",IF(C1689="","cargar","pagado")) -> pagado | I1689: =+YEAR(B1689) -> 2026 | J1689: =+MONTH(B1689) -> 2
A1690: CH/RECIB48 | B1690: 26/02/2026 | C1690: 91002896 | D1690: 140 | E1690: -100000000 | F1690: CHEQUE P/CAMARA | G1690: 0 | H1690: =+IF(B1690>'sap nuevo'!$V$1,"cargar",IF(C1690="","cargar","pagado")) -> cargar | I1690: =+YEAR(B1690) -> 2026 | J1690: =+MONTH(B1690) -> 2
A1691: CH/PAG | B1691: 26/02/2026 | C1691: 91002900 | D1691: 140 | E1691: -13349996 | F1691: CHEQUE CANJE INTERNO | G1691: 0 | H1691: =+IF(B1691>'sap nuevo'!$V$1,"cargar",IF(C1691="","cargar","pagado")) -> cargar | I1691: =+YEAR(B1691) -> 2026 | J1691: =+MONTH(B1691) -> 2
A1692: CH/PAG | B1692: 26/02/2026 | C1692: 91002901 | D1692: 140 | E1692: -10913343 | F1692: CHEQUE CANJE INTERNO | G1692: 0 | H1692: =+IF(B1692>'sap nuevo'!$V$1,"cargar",IF(C1692="","cargar","pagado")) -> cargar | I1692: =+YEAR(B1692) -> 2026 | J1692: =+MONTH(B1692) -> 2
A1693: CH/PAG | B1693: 26/02/2026 | C1693: 91002899 | D1693: 140 | E1693: -9568920.7 | F1693: CHEQUE CANJE INTERNO | G1693: 0 | H1693: =+IF(B1693>'sap nuevo'!$V$1,"cargar",IF(C1693="","cargar","pagado")) -> cargar | I1693: =+YEAR(B1693) -> 2026 | J1693: =+MONTH(B1693) -> 2
A1694: CH/RECIB48 | B1694: 26/02/2026 | C1694: 91002861 | D1694: 140 | E1694: -8895951.4 | F1694: CHEQUE P/CAMARA | G1694: 0 | H1694: =+IF(B1694>'sap nuevo'!$V$1,"cargar",IF(C1694="","cargar","pagado")) -> cargar | I1694: =+YEAR(B1694) -> 2026 | J1694: =+MONTH(B1694) -> 2
A1695: CH/RECIB48 | B1695: 26/02/2026 | C1695: 91002895 | D1695: 140 | E1695: -8719172.5 | F1695: CHEQUE P/CAMARA | G1695: 0 | H1695: =+IF(B1695>'sap nuevo'!$V$1,"cargar",IF(C1695="","cargar","pagado")) -> cargar | I1695: =+YEAR(B1695) -> 2026 | J1695: =+MONTH(B1695) -> 2
A1696: CH/RECIB48 | B1696: 26/02/2026 | C1696: 91002903 | D1696: 140 | E1696: -6046035.9 | F1696: CHEQUE P/CAMARA | G1696: 0 | H1696: =+IF(B1696>'sap nuevo'!$V$1,"cargar",IF(C1696="","cargar","pagado")) -> cargar | I1696: =+YEAR(B1696) -> 2026 | J1696: =+MONTH(B1696) -> 2
A1697: CH/RECIB48 | B1697: 27/02/2026 | C1697: 91002897 | D1697: 140 | E1697: -1.1237572e+08 | F1697: CHEQUE P/CAMARA | G1697: 0 | H1697: =+IF(B1697>'sap nuevo'!$V$1,"cargar",IF(C1697="","cargar","pagado")) -> cargar | I1697: =+YEAR(B1697) -> 2026 | J1697: =+MONTH(B1697) -> 2
A1698: CH/RECIB48 | B1698: 27/02/2026 | C1698: 91002898 | D1698: 140 | E1698: -26463187 | F1698: CHEQUE P/CAMARA | G1698: 0 | H1698: =+IF(B1698>'sap nuevo'!$V$1,"cargar",IF(C1698="","cargar","pagado")) -> cargar | I1698: =+YEAR(B1698) -> 2026 | J1698: =+MONTH(B1698) -> 2
A1699: CH/PAG | B1699: 27/02/2026 | C1699: 91002851 | D1699: 140 | E1699: -5275000 | F1699: CHEQUE CANJE INTERNO | G1699: 0 | H1699: =+IF(B1699>'sap nuevo'!$V$1,"cargar",IF(C1699="","cargar","pagado")) -> cargar | I1699: =+YEAR(B1699) -> 2026 | J1699: =+MONTH(B1699) -> 2
A1700: CH/RECIB48 | B1700: 27/02/2026 | C1700: 91002877 | D1700: 140 | E1700: -4503359.4 | F1700: CHEQUE P/CAMARA | G1700: 0 | H1700: =+IF(B1700>'sap nuevo'!$V$1,"cargar",IF(C1700="","cargar","pagado")) -> cargar | I1700: =+YEAR(B1700) -> 2026 | J1700: =+MONTH(B1700) -> 2
A1701: CH/RECIB48 | B1701: 03/03/2026 | C1701: 91002883 | D1701: 140 | E1701: -13150000 | F1701: CHEQUE P/CAMARA | G1701: 0 | H1701: =+IF(B1701>'sap nuevo'!$V$1,"cargar",IF(C1701="","cargar","pagado")) -> cargar | I1701: =+YEAR(B1701) -> 2026 | J1701: =+MONTH(B1701) -> 3
... A1784: CH/RECIB48 | B1784: 13/04/2026 | C1784: 91002973 | D1784: 140 | E1784: -5739462.2 | F1784: CHEQUE P/CAMARA | G1784: 0 | H1784: =+IF(B1784>'sap nuevo'!$V$1,"cargar",IF(C1784="","cargar","pagado")) -> cargar | I1784: =+YEAR(B1784) -> 2026 | J1784: =+MONTH(B1784) -> 4
A1785: CH/RECIB48 | B1785: 46126 | C1785: 91002986 | D1785: 140 | E1785: -2527351.8 | F1785: CHEQUE P/CAMARA | G1785: 0 | H1785: =+IF(B1785>'sap nuevo'!$V$1,"cargar",IF(C1785="","cargar","pagado")) -> pagado | I1785: =+YEAR(B1785) -> 2026 | J1785: =+MONTH(B1785) -> 4
A1786: CH/RECIB48 | B1786: 46126 | C1786: 91002985 | D1786: 140 | E1786: -4290889.2 | F1786: CHEQUE P/CAMARA | G1786: 0 | H1786: =+IF(B1786>'sap nuevo'!$V$1,"cargar",IF(C1786="","cargar","pagado")) -> pagado | I1786: =+YEAR(B1786) -> 2026 | J1786: =+MONTH(B1786) -> 4
A1787: CH/RECIB48 | B1787: 46126 | C1787: 91002984 | D1787: 140 | E1787: -2040745 | F1787: CHEQUE P/CAMARA | G1787: 0 | H1787: =+IF(B1787>'sap nuevo'!$V$1,"cargar",IF(C1787="","cargar","pagado")) -> pagado | I1787: =+YEAR(B1787) -> 2026 | J1787: =+MONTH(B1787) -> 4
A1788: CH/RECIB48 | B1788: 46126 | C1788: 91002980 | D1788: 140 | E1788: -19457607 | F1788: CHEQUE P/CAMARA | G1788: 0 | H1788: =+IF(B1788>'sap nuevo'!$V$1,"cargar",IF(C1788="","cargar","pagado")) -> pagado | I1788: =+YEAR(B1788) -> 2026 | J1788: =+MONTH(B1788) -> 4
A1789: CH/RECIB48 | B1789: 46126 | C1789: 91002979 | D1789: 140 | E1789: -16593343 | F1789: CHEQUE P/CAMARA | G1789: 0 | H1789: =+IF(B1789>'sap nuevo'!$V$1,"cargar",IF(C1789="","cargar","pagado")) -> pagado | I1789: =+YEAR(B1789) -> 2026 | J1789: =+MONTH(B1789) -> 4
A1790: CH/RECIB48 | B1790: 46126 | C1790: 91002884 | D1790: 140 | E1790: -13120318 | F1790: CHEQUE P/CAMARA | G1790: 0 | H1790: =+IF(B1790>'sap nuevo'!$V$1,"cargar",IF(C1790="","cargar","pagado")) -> pagado | I1790: =+YEAR(B1790) -> 2026 | J1790: =+MONTH(B1790) -> 4
A1791: CH/RECIB48 | B1791: 46127 | C1791: 91002983 | D1791: 140 | E1791: -2243665.8 | F1791: CHEQUE P/CAMARA | G1791: 0 | H1791: =+IF(B1791>'sap nuevo'!$V$1,"cargar",IF(C1791="","cargar","pagado")) -> pagado | I1791: =+YEAR(B1791) -> 2026 | J1791: =+MONTH(B1791) -> 4
A1792: CH/RECIB48 | B1792: 46128 | C1792: 91002993 | D1792: 140 | E1792: -1.7385189e+08 | F1792: CHEQUE P/CAMARA | G1792: 0 | H1792: =+IF(B1792>'sap nuevo'!$V$1,"cargar",IF(C1792="","cargar","pagado")) -> pagado | I1792: =+YEAR(B1792) -> 2026 | J1792: =+MONTH(B1792) -> 4
A1793: CH/RECIB48 | B1793: 46128 | C1793: 91002987 | D1793: 140 | E1793: -44368343 | F1793: CHEQUE P/CAMARA | G1793: 0 | H1793: =+IF(B1793>'sap nuevo'!$V$1,"cargar",IF(C1793="","cargar","pagado")) -> pagado | I1793: =+YEAR(B1793) -> 2026 | J1793: =+MONTH(B1793) -> 4
A1794: CH/RECIB48 | B1794: 46128 | C1794: 91003006 | D1794: 140 | E1794: -27269382 | F1794: CHEQUE P/CAMARA | G1794: 0 | H1794: =+IF(B1794>'sap nuevo'!$V$1,"cargar",IF(C1794="","cargar","pagado")) -> pagado | I1794: =+YEAR(B1794) -> 2026 | J1794: =+MONTH(B1794) -> 4
A1795: CH/RECIB48 | B1795: 46128 | C1795: 91002990 | D1795: 140 | E1795: -22548375 | F1795: CHEQUE P/CAMARA | G1795: 0 | H1795: =+IF(B1795>'sap nuevo'!$V$1,"cargar",IF(C1795="","cargar","pagado")) -> pagado | I1795: =+YEAR(B1795) -> 2026 | J1795: =+MONTH(B1795) -> 4
A1796: CH/RECIB48 | B1796: 46128 | C1796: 91002995 | D1796: 140 | E1796: -15085000 | F1796: CHEQUE P/CAMARA | G1796: 0 | H1796: =+IF(B1796>'sap nuevo'!$V$1,"cargar",IF(C1796="","cargar","pagado")) -> pagado | I1796: =+YEAR(B1796) -> 2026 | J1796: =+MONTH(B1796) -> 4
...

Sheet cheques a conf
A1: Numero CH | B1: Fecha | C1: Importe | D1: Estado | E1: Banco
A2: 91003542 | B2: 04/09/202 | C2: -27505451 | D2: =+IF(A2="","cargar","clearing") -> clearing | E2: =VLOOKUP(A2,'sap nuevo'!E:H,4,FALSE) -> MACRO
A3: 91003545 | B3: 04/09/202 | C3: -10473653 | D3: =+IF(A3="","cargar","clearing") -> clearing | E3: =VLOOKUP(A3,'sap nuevo'!E:H,4,FALSE) -> MACRO
A4: 91003547 | B4: 04/09/202 | C4: -9474131.5 | D4: =+IF(A4="","cargar","clearing") -> clearing | E4: =VLOOKUP(A4,'sap nuevo'!E:H,4,FALSE) -> MACRO
A5: 91003549 | B5: 04/09/202 | C5: -11817540 | D5: =+IF(A5="","cargar","clearing") -> clearing | E5: =VLOOKUP(A5,'sap nuevo'!E:H,4,FALSE) -> MACRO
A6: 91003550 | B6: 04/09/202 | C6: -15450714 | D6: =+IF(A6="","cargar","clearing") -> clearing | E6: =VLOOKUP(A6,'sap nuevo'!E:H,4,FALSE) -> MACRO
A7: 91003551 | B7: 04/09/202 | C7: -11365560 | D7: =+IF(A7="","cargar","clearing") -> clearing | E7: =VLOOKUP(A7,'sap nuevo'!E:H,4,FALSE) -> MACRO
A8: 91003554 | B8: 04/09/202 | C8: -12576900 | D8: =+IF(A8="","cargar","clearing") -> clearing | E8: =VLOOKUP(A8,'sap nuevo'!E:H,4,FALSE) -> MACRO
D9: =+IF(A9="","cargar","clearing") -> cargar | E9: =VLOOKUP(A9,'sap nuevo'!E:H,4,FALSE) -> #N/A
D10: =+IF(A10="","cargar","clearing") -> cargar | E10: =VLOOKUP(A10,'sap nuevo'!E:H,4,FALSE) -> #N/A
D11: =+IF(A11="","cargar","clearing") -> cargar | E11: =VLOOKUP(A11,'sap nuevo'!E:H,4,FALSE) -> #N/A
D12: =+IF(A12="","cargar","clearing") -> cargar | E12: =VLOOKUP(A12,'sap nuevo'!E:H,4,FALSE) -> #N/A
D13: =+IF(A13="","cargar","clearing") -> cargar | E13: =VLOOKUP(A13,'sap nuevo'!E:H,4,FALSE) -> #N/A
D14: =+IF(A14="","cargar","clearing") -> cargar | E14: =VLOOKUP(A14,'sap nuevo'!E:H,4,FALSE) -> #N/A
D15: =+IF(A15="","cargar","clearing") -> cargar | E15: =VLOOKUP(A15,'sap nuevo'!E:H,4,FALSE) -> #N/A
D16: =+IF(A16="","cargar","clearing") -> cargar | E16: =VLOOKUP(A16,'sap nuevo'!E:H,4,FALSE) -> #N/A
D17: =+IF(A17="","cargar","clearing") -> cargar | E17: =VLOOKUP(A17,'sap nuevo'!E:H,4,FALSE) -> #N/A
D18: =+IF(A18="","cargar","clearing") -> cargar | E18: =VLOOKUP(A18,'sap nuevo'!E:H,4,FALSE) -> #N/A
D19: =+IF(A19="","cargar","clearing") -> cargar | E19: =VLOOKUP(A19,'sap nuevo'!E:H,4,FALSE) -> #N/A
D20: =+IF(A20="","cargar","clearing") -> cargar | E20: =VLOOKUP(A20,'sap nuevo'!E:H,4,FALSE) -> #N/A
... D43: =+IF(A43="","cargar","clearing") -> cargar | E43: =VLOOKUP(A43,'sap nuevo'!E:H,4,FALSE) -> #N/A

Sheet resumen viejo
A1: EMPRESA: CITRUSVIL SA | D1: - | E1: GALICIA | F1: MACRO | G1: Totales
A2: Cheques a Conformar | C2: =TODAY() -> 46272 | D2: 0 | E2: =IFERROR(GETPIVOTDATA("importe",$Q$12,"Banco","GALICIA"),0) -> 0 | F2: =IFERROR(GETPIVOTDATA("importe",$Q$12,"Banco","MACRO"),0) -> 98663950 | G2: =+D2+E2+F2 -> 98663950
A4: Cheques Pendientes al | C4: =+TODAY()-1 -> 46271 | D4: 0 | E4: =IFERROR(GETPIVOTDATA("importe",$A$13,"Banco","GALICIA")-E2, 0) -> 0 | F4: =IFERROR(GETPIVOTDATA("importe",$A$13,"Banco","MACRO")-F2,0) -> 94643521 | G4: =+D4+E4+F4 -> 94643521
A5: Cheques a Vencer Semana 07/09 al 11/09 | D5: 0 | E5: =SUM(K12) -> 0 | F5: =SUM(L14:L22) -> 1.3943544e+08 | G5: =+D5+E5+F5 -> 1.3943544e+08
A6: Cheques a Vencer Semana 14/09 al 18/09 | D6: 0 | E6: =SUM(K13) -> 0 | F6: =SUM(L13) -> 0 | G6: =+D6+E6+F6 -> 0
A7: Cheques a Vencer Semana 21/09 en adelante | D7: 0 | E7: =SUM(K13) -> 0 | F7: =SUM(L23:L29) -> 47536960 | G7: =+D7+E7+F7 -> 47536960
A8: Totales | D8: =+D4+D5+D2+D6+D7 -> 0 | E8: =+E4+E5+E2+E6+E7 -> 0 | F8: =+F4+F5+F2+F6+F7 -> 3.8027987e+08 | G8: =+D8+E8+F8 -> 3.8027987e+08
J9: estado dos | K9: proximo a vencer | Q9: CHEQUES A PAGAR EN EL DÍA
A10: CHEQUES PENDIENTES POR COBRAR | J10: estado tres | K10: (Todas) | Q10: en cartera | R10: clearing
A11: estado dos | B11: a pagar
J12: Suma de importe | L12: Etiquetas de columna | Q12: Suma de importe | S12: Etiquetas de columna
A13: Suma de importe | C13: Etiquetas de columna | J13: Etiquetas de fila | K13: numero de cheque | L13: MACRO | M13: Total general | Q13: Etiquetas de fila | R13: Fe.valor | S13: MACRO | T13: Total general
A14: Etiquetas de fila | B14: Fe.valor | C14: MACRO | D14: Total general | J14: 46272 | K14: 91003259 | L14: 11000000 | M14: 11000000 | Q14: 91003542 | R14: 46269 | S14: 27505451 | T14: 27505451
A15: 91003494 | B15: 46260 | C15: 3576314.4 | D15: 3576314.4 | K15: 91003556 | L15: 38917368 | M15: 38917368 | Q15: 91003545 | R15: 46268 | S15: 10473653 | T15: 10473653
A16: 91003503 | B16: 46260 | C16: 3910060.3 | D16: 3910060.3 | K16: 91003557 | L16: 5935943.4 | M16: 5935943.4 | Q16: 91003547 | R16: 46269 | S16: 9474131.5 | T16: 9474131.5
A17: 91003507 | B17: 46260 | C17: 4464734.3 | D17: 4464734.3 | K17: 91003558 | L17: 5305667.9 | M17: 5305667.9 | Q17: 91003549 | R17: 46269 | S17: 11817540 | T17: 11817540
A18: 91003512 | B18: 46260 | C18: 2165486 | D18: 2165486 | K18: 91003559 | L18: 11555763 | M18: 11555763 | Q18: 91003550 | R18: 46269 | S18: 15450714 | T18: 15450714
A19: 66622027 | B19: 46260 | C19: 8397402.3 | D19: 8397402.3 | K19: 91003560 | L19: 16859868 | M19: 16859868 | Q19: 91003551 | R19: 46269 | S19: 11365560 | T19: 11365560
A20: 91003536 | B20: 46266 | C20: 7610257.7 | D20: 7610257.7 | K20: 91003561 | L20: 17393857 | M20: 17393857 | Q20: 91003554 | R20: 46269 | S20: 12576900 | T20: 12576900
A21: 91003542 | B21: 46269 | C21: 27505451 | D21: 27505451 | J21: 46275 | K21: 61301871 | L21: 21466973 | M21: 21466973 | Q21: Total general | S21: 98663950 | T21: 98663950
A22: 91003544 | B22: 46267 | C22: 42236088 | D22: 42236088 | K22: 91003371 | L22: 11000000 | M22: 11000000
A23: 91003545 | B23: 46268 | C23: 10473653 | D23: 10473653 | J23: 46288 | K23: 91002858 | L23: 5275000 | M23: 5275000
A24: 91003546 | B24: 46269 | C24: 5357588.5 | D24: 5357588.5 | J24: 46300 | K24: 61301874 | L24: 2500000 | M24: 2500000
A25: 91003547 | B25: 46269 | C25: 9474131.5 | D25: 9474131.5 | K25: 91003260 | L25: 11000000 | M25: 11000000
A26: 91003548 | B26: 46269 | C26: 2764712.9 | D26: 2764712.9 | J26: 46304 | K26: 91003372 | L26: 10124651 | M26: 10124651
A27: 91003549 | B27: 46269 | C27: 11817540 | D27: 11817540 | J27: 46318 | K27: 91002859 | L27: 5278371.4 | M27: 5278371.4
A28: 91003550 | B28: 46269 | C28: 15450714 | D28: 15450714 | J28: 46331 | K28: 61301875 | L28: 2265052.5 | M28: 2265052.5
A29: 91003551 | B29: 46269 | C29: 11365560 | D29: 11365560 | K29: 91003261 | L29: 11093885 | M29: 11093885
A30: 91003553 | B30: 46269 | C30: 7359300 | D30: 7359300 | J30: Total general | L30: 1.869724e+08 | M30: 1.869724e+08
A31: 91003554 | B31: 46269 | C31: 12576900 | D31: 12576900
A32: 91003555 | B32: 46269 | C32: 6801576 | D32: 6801576
A33: Total general | C33: 1.9330747e+08 | D33: 1.9330747e+08

Sheet Hoja1
I1: numero de cheque | J1: Usuario | K1: importe | L1: Fe.valor
I2: 3045959 | J2: COMBUSTIBLES DEL NORTE S.A. LAS LAJITAS 09 | K2: 6923300.1 | L2: 45663
A3: Cheque | B3: Proveedor | C3: Importe | D3: Fecha de pago | I3: 3045960 | J3: FRANCO DANIEL EDELMIRO JOAQUIN V GONZALEZ 09 | K3: 3021563.4 | L3: 45663
A4: 71643815 | B4: CONSORCIO DE CAMINOS INDEPENDENCIA | C4: =VLOOKUP(A4,I:L,3,FALSE) -> 7802392 | D4: =VLOOKUP(A4,I:L,4,FALSE) -> 46114 | I4: 3045961 | J4: CATALANA DE SERVICIOS SRL YERBA BUENA 14 | K4: 6282395.4 | L4: 45663
A5: 73815758 | B5: Vetifarma S.A. | C5: =VLOOKUP(A5,I:L,3,FALSE) -> 2417460.5 | D5: =VLOOKUP(A5,I:L,4,FALSE) -> 46099 | I5: 3045962 | J5: CONTROL UNION NORTE S.A YERBA BUENA 14 | K5: 2160608.6 | L5: 45663
A6: 73815773 | B6: MARTINO HNOS SERVICIOS AGRICOLAS | C6: =VLOOKUP(A6,I:L,3,FALSE) -> 19791686 | D6: =VLOOKUP(A6,I:L,4,FALSE) -> 46113 | I6: 3045963 | J6: GARCIA ALBESA MONICA GABRIELA JOAQUIN V. GONZALEZ 09 | K6: 7003929.5 | L6: 45664
A7: 73815781 | B7: BRANDAN FEDERICO NICOLAS | C7: =VLOOKUP(A7,I:L,3,FALSE) -> 5890723.4 | D7: =VLOOKUP(A7,I:L,4,FALSE) -> 46112 | I7: 3045964 | J7: LINCE S.A. VILLA NUEVA 03 | K7: 16987515 | L7: 45664
A8: 73815783 | B8: Centro Ganadero S.R.L. | C8: =VLOOKUP(A8,I:L,3,FALSE) -> 14446592 | D8: =VLOOKUP(A8,I:L,4,FALSE) -> 46113 | I8: 3045958 | J8: TFP CONSTRUCCIONES SRL SALTA 09 | K8: 34672682 | L8: 45660
A9: 73815787 | B9: Pulmajo S.R.L. | C9: =VLOOKUP(A9,I:L,3,FALSE) -> 1181043.9 | D9: =VLOOKUP(A9,I:L,4,FALSE) -> 46111 | I9: 93655828 | J9: Pulmajo S.R.L. | K9: 3708721.2 | L9: 45667
A10: 73815789 | B10: DEL BASSO MANLIO ALEJANDRO | C10: =VLOOKUP(A10,I:L,3,FALSE) -> 6486668.3 | D10: =VLOOKUP(A10,I:L,4,FALSE) -> 46111 | I10: 93919608 | J10: Agro Yutuyaco S.R.L. Laferrere 01 | K10: 6224594.3 | L10: 45670
A11: 73815792 | B11: LANGELLA JUAN RODOLFO | C11: =VLOOKUP(A11,I:L,3,FALSE) -> 1285199.1 | D11: =VLOOKUP(A11,I:L,4,FALSE) -> 46119 | I11: 93919609 | J11: PETROARSA S.A SAN MIGUEL DE TUCUMAN 14 | K11: 10810851 | L11: 45670
A12: 73815793 | B12: CRESPI GABRIEL ALFREDO | C12: =VLOOKUP(A12,I:L,3,FALSE) -> 3366049.8 | D12: =VLOOKUP(A12,I:L,4,FALSE) -> 46119 | I12: 95363988 | J12: ROJAS NICOLAS ALBERTO ACONQUIJA 02 | K12: 14814902 | L12: 45670
A13: 73815794 | B13: Villa y Moreno S.A. | C13: =VLOOKUP(A13,I:L,3,FALSE) -> 9456251.7 | D13: =VLOOKUP(A13,I:L,4,FALSE) -> 46119 | I13: 95363989 | J13: LINCE S.A. VILLA NUEVA 03 | K13: 13000000 | L13: 45670
A14: 73815795 | B14: SOUK S. A. S. | C14: =VLOOKUP(A14,I:L,3,FALSE) -> 14112823 | D14: =VLOOKUP(A14,I:L,4,FALSE) -> 46119 | I14: 95363990 | J14: LINCE S.A. VILLA NUEVA 03 | K14: 12640528 | L14: 45671
A15: 73815796 | B15: Fundacion Anta Ganadera | C15: =VLOOKUP(A15,I:L,3,FALSE) -> 1073500 | D15: =VLOOKUP(A15,I:L,4,FALSE) -> 46119 | I15: 95363991 | J15: TRANSPORTE EL SALTEÑO SRL SALTA 09 | K15: 15000000 | L15: 45670
... A25: 73815681 | B25: Agricola Garcia S.A. | C25: =VLOOKUP(A25,I:L,3,FALSE) -> 8400000 | D25: =VLOOKUP(A25,I:L,4,FALSE) -> 46121 | I25: 95363994 | J25: CATALANA DE SERVICIOS SRL YERBA BUENA 14 | K25: 5259947.8 | L25: 45677
C26: =VLOOKUP(A26,I:L,3,FALSE) -> #N/A | D26: =VLOOKUP(A26,I:L,4,FALSE) -> #N/A | I26: 95363995 | J26: RODRIGUEZ NESTOR HORACIO YERBA BUENA 14 | K26: 14747366 | L26: 45677
C27: =VLOOKUP(A27,I:L,3,FALSE) -> #N/A | D27: =VLOOKUP(A27,I:L,4,FALSE) -> #N/A | I27: 95363996 | J27: Agro Yutuyaco S.R.L. Laferrere 01 | K27: 5817326.5 | L27: 45677
C28: =VLOOKUP(A28,I:L,3,FALSE) -> #N/A | D28: =VLOOKUP(A28,I:L,4,FALSE) -> #N/A | I28: 95363997 | J28: Turbay Pablo Facundo JOAQUIN V. GONZALEZ 09 | K28: 11737631 | L28: 45677
C29: =VLOOKUP(A29,I:L,3,FALSE) -> #N/A | D29: =VLOOKUP(A29,I:L,4,FALSE) -> #N/A | I29: 95363998 | J29: MARTINEZ LUIS FELIPE joaquin b gonzalez Salta 03 | K29: 13000000 | L29: 45678
C30: =VLOOKUP(A30,I:L,3,FALSE) -> #N/A | D30: =VLOOKUP(A30,I:L,4,FALSE) -> #N/A | I30: 95363999 | J30: MARTINEZ LUIS FELIPE joaquin b gonzalez Salta 03 | K30: 13721032 | L30: 45679
C31: =VLOOKUP(A31,I:L,3,FALSE) -> #N/A | D31: =VLOOKUP(A31,I:L,4,FALSE) -> #N/A | I31: 95364000 | J31: FANTINI-LOPEZ EL CALDEN AGROS JESUS MARIA 14 | K31: 20000000 | L31: 45678
C32: =VLOOKUP(A32,I:L,3,FALSE) -> #N/A | D32: =VLOOKUP(A32,I:L,4,FALSE) -> #N/A | I32: 95364001 | J32: FANTINI-LOPEZ EL CALDEN AGROS JESUS MARIA 14 | K32: 19766069 | L32: 45679
C33: =VLOOKUP(A33,I:L,3,FALSE) -> #N/A | D33: =VLOOKUP(A33,I:L,4,FALSE) -> #N/A | I33: 95364002 | J33: SERV.AGROP VILLA PAPADAKIS S.RSALTA 09 | K33: 17000000 | L33: 45678
C34: =VLOOKUP(A34,I:L,3,FALSE) -> #N/A | D34: =VLOOKUP(A34,I:L,4,FALSE) -> #N/A | I34: 95364003 | J34: SERV.AGROP VILLA PAPADAKIS S.RSALTA 09 | K34: 19263402 | L34: 45679
C35: =VLOOKUP(A35,I:L,3,FALSE) -> #N/A | D35: =VLOOKUP(A35,I:L,4,FALSE) -> #N/A | I35: 3045972 | J35: IKURRIÑA SRL GENERAL RIVAS 01 | K35: 5638258.6 | L35: 45681
C36: =VLOOKUP(A36,I:L,3,FALSE) -> #N/A | D36: =VLOOKUP(A36,I:L,4,FALSE) -> #N/A | I36: 3045973 | J36: SUAREZ GABRIEL SEBASTIAN SANTIAGO DEL ESTERO 13 | K36: 14278043 | L36: 45681
C37: =VLOOKUP(A37,I:L,3,FALSE) -> #N/A | D37: =VLOOKUP(A37,I:L,4,FALSE) -> #N/A | I37: 3045974 | J37: Vetifarma S.A. Parque Ind."La Plata 01 | K37: 9618299.6 | L37: 45681
... C48: =VLOOKUP(A48,I:L,3,FALSE) -> #N/A | D48: =VLOOKUP(A48,I:L,4,FALSE) -> #N/A | I48: 3045985 | J48: HACIENDAS VILLAGUAY SRL Villaguay 05 | K48: 107900000 | L48: 45712
I49: 3045986 | J49: HACIENDAS VILLAGUAY SRL Villaguay 05 | K49: 65540829 | L49: 45741
I50: 95364004 | J50: HERRERA NESTOR ARIEL ALDERETES 14 | K50: 12631434 | L50: 45686
I51: 95364005 | J51: Centro Ganadero S.R.L. Las Lajits 09 | K51: 21000000 | L51: 45688
I52: 95364006 | J52: Centro Ganadero S.R.L. Las Lajits 09 | K52: 21949760 | L52: 45691
I53: 95364007 | J53: FANTINI-LOPEZ EL CALDEN AGROS JESUS MARIA 14 | K53: 8544851.5 | L53: 45687
I54: 95364008 | J54: CONSORCIO DE CAMINOS INDEPENDESALTA 09 | K54: 23375322 | L54: 45687
I55: 55259926 | J55: EDET S.A. SAN MIGUEL DE TUCUMAN 14 | K55: 2443870 | L55: 45687
I56: 55259927 | J56: Pulmajo S.R.L. CONCEPCION 14 | K56: 1000000 | L56: 45693
I57: 55259928 | J57: Pulmajo S.R.L. CONCEPCION 14 | K57: 2000000 | L57: 45693
I58: 55259929 | J58: Pulmajo S.R.L. CONCEPCION 14 | K58: 1075735.7 | L58: 45693
I59: 95364009 | J59: TUCUMAN BBS SRL SAN MIGUEL DE TUCUMAN 14 | K59: 156355.8 | L59: 45695
...

Sheet RESUMEN
A2: AGROGANADERA DEL NOA S.A. — Control de Cheques
A3: =TODAY() -> 46272
A5: CHEQUES A CONFORMAR HOY
A6: Nº Cheque | B6: Fecha | C6: Importe | D6: Banco
A7: ='cheques a conf'!A2 -> 91003542 | B7: ='cheques a conf'!B2 -> 04/09/202 | C7: =IF('cheques a conf'!C2<>"",-'cheques a conf'!C2,"") -> 27505451 | D7: =IF('cheques a conf'!C2<>"",'cheques a conf'!E2,"") -> MACRO
A8: ='cheques a conf'!A3 -> 91003545 | B8: ='cheques a conf'!B3 -> 04/09/202 | C8: =IF('cheques a conf'!C3<>"",-'cheques a conf'!C3,"") -> 10473653 | D8: =IF('cheques a conf'!C3<>"",'cheques a conf'!E3,"") -> MACRO
A9: ='cheques a conf'!A4 -> 91003547 | B9: ='cheques a conf'!B4 -> 04/09/202 | C9: =IF('cheques a conf'!C4<>"",-'cheques a conf'!C4,"") -> 9474131.5 | D9: =IF('cheques a conf'!C4<>"",'cheques a conf'!E4,"") -> MACRO
A10: ='cheques a conf'!A5 -> 91003549 | B10: ='cheques a conf'!B5 -> 04/09/202 | C10: =IF('cheques a conf'!C5<>"",-'cheques a conf'!C5,"") -> 11817540 | D10: =IF('cheques a conf'!C5<>"",'cheques a conf'!E5,"") -> MACRO
A11: ='cheques a conf'!A6 -> 91003550 | B11: ='cheques a conf'!B6 -> 04/09/202 | C11: =IF('cheques a conf'!C6<>"",-'cheques a conf'!C6,"") -> 15450714 | D11: =IF('cheques a conf'!C6<>"",'cheques a conf'!E6,"") -> MACRO
A12: ='cheques a conf'!A7 -> 91003551 | B12: ='cheques a conf'!B7 -> 04/09/202 | C12: =IF('cheques a conf'!C7<>"",-'cheques a conf'!C7,"") -> 11365560 | D12: =IF('cheques a conf'!C7<>"",'cheques a conf'!E7,"") -> MACRO
A13: ='cheques a conf'!A8 -> 91003554 | B13: ='cheques a conf'!B8 -> 04/09/202 | C13: =IF('cheques a conf'!C8<>"",-'cheques a conf'!C8,"") -> 12576900 | D13: =IF('cheques a conf'!C8<>"",'cheques a conf'!E8,"") -> MACRO
A14: ='cheques a conf'!A9 -> 0 | B14: ='cheques a conf'!B9 -> 0 | C14: =IF('cheques a conf'!C9<>"",-'cheques a conf'!C9,"") | D14: =IF('cheques a conf'!C9<>"",'cheques a conf'!E9,"")
A15: ='cheques a conf'!A10 -> 0 | B15: ='cheques a conf'!B10 -> 0 | C15: =IF('cheques a conf'!C10<>"",-'cheques a conf'!C10,"") | D15: =IF('cheques a conf'!C10<>"",'cheques a conf'!E10,"")
A16: ='cheques a conf'!A11 -> 0 | B16: ='cheques a conf'!B11 -> 0 | C16: =IF('cheques a conf'!C11<>"",-'cheques a conf'!C11,"") | D16: =IF('cheques a conf'!C11<>"",'cheques a conf'!E11,"")
A17: ='cheques a conf'!A12 -> 0 | B17: ='cheques a conf'!B12 -> 0 | C17: =IF('cheques a conf'!C12<>"",-'cheques a conf'!C12,"") | D17: =IF('cheques a conf'!C12<>"",'cheques a conf'!E12,"")
A18: ='cheques a conf'!A13 -> 0 | B18: ='cheques a conf'!B13 -> 0 | C18: =IF('cheques a conf'!C13<>"",-'cheques a conf'!C13,"") | D18: =IF('cheques a conf'!C13<>"",'cheques a conf'!E13,"")
... A26: ='cheques a conf'!A21 -> 0 | B26: ='cheques a conf'!B21 -> 0 | C26: =IF('cheques a conf'!C21<>"",-'cheques a conf'!C21,"") | D26: =IF('cheques a conf'!C21<>"",'cheques a conf'!E21,"")
A27: TOTAL A CONFORMAR | C27: =SUMIF('cheques a conf'!C2:C100,"<0",'cheques a conf'!C2:C100)*-1 -> 98663950
A29: CHEQUES A PAGAR
A30: Concepto | B30: GALICIA | C30: MACRO | D30: Total
A31: Cheques a conformar hoy | B31: =SUMIF(D7:D26,B30,C7:C26) -> 0 | C31: =SUMIF(D7:D26,C30,C7:C26) -> 98663950 | D31: =B31+C31 -> 98663950
A32: Cheques pendientes vencen esta semana | B32: {=SUMPRODUCT(('sap nuevo'!H$2:H$9987="GALICIA")*('sap nuevo'!J$2:J$9987="en periodo de pago")*('sap nuevo'!G$2:G$9987<=TODAY()-WEEKDAY(TODAY(),2)+5)*('sap nuevo'!F$2:F$9987))-B31} -> 0 | C32: {=SUMPRODUCT(('sap nuevo'!H$2:H$9987="MACRO")*('sap nuevo'!J$2:J$9987="en periodo de pago")*('sap nuevo'!G$2:G$9987<=TODAY()-WEEKDAY(TODAY(),2)+5)*('sap nuevo'!F$2:F$9987))-C31} -> 2.3407896e+08 | D32: =B32+C32 -> 2.3407896e+08
A33: Cheques que vencen en la próxima semana | B33: {=SUMPRODUCT(('sap nuevo'!H$2:H$9987="GALICIA")*('sap nuevo'!J$2:J$9987="en periodo de pago")*('sap nuevo'!G$2:G$9987>=TODAY()-WEEKDAY(TODAY(),2)+8)*('sap nuevo'!G$2:G$9987<=TODAY()-WEEKDAY(TODAY(),2)+14)*('sap nuevo'!F$2:F$9987))} -> 0 | C33: {=SUMPRODUCT(('sap nuevo'!H$2:H$9987="MACRO")*('sap nuevo'!J$2:J$9987="en periodo de pago")*('sap nuevo'!G$2:G$9987>=TODAY()-WEEKDAY(TODAY(),2)+6)*('sap nuevo'!G$2:G$9987<=TODAY()-WEEKDAY(TODAY(),2)+14)*('sap nuevo'!F$2:F$9987))} -> 0 | D33: =B33+C33 -> 0
A34: Cheques que vencen en más de 15 días | B34: {=SUMPRODUCT(('sap nuevo'!H$2:H$9987="GALICIA")*('sap nuevo'!J$2:J$9987="en periodo de pago")*('sap nuevo'!G$2:G$9987>TODAY()+15)*('sap nuevo'!F$2:F$9987))} -> 0 | C34: {=SUMPRODUCT(('sap nuevo'!H$2:H$9987="MACRO")*('sap nuevo'!J$2:J$9987="en periodo de pago")*('sap nuevo'!G$2:G$9987>=TODAY()-WEEKDAY(TODAY(),2)+15)*('sap nuevo'!F$2:F$9987))} -> 47536960 | D34: =B34+C34 -> 47536960
A35: TOTAL CHEQUES A PAGAR | B35: =B31+B32+B33+B34 -> 0 | C35: =C31+C32+C33+C34 -> 3.8027987e+08 | D35: =D31+D32+D33+D34 -> 3.8027987e+08
A37: CHEQUES CADUCADOS / FUERA DE FECHA
A38: Banco | B38: Cantidad | C38: Importe Total | D38: —
A39: GALICIA | B39: =COUNTIFS('sap nuevo'!H$2:H$9987,"GALICIA",'sap nuevo'!J$2:J$9987,"fuera de fecha",'sap nuevo'!F$2:F$9987,">0") -> 6 | C39: {=SUMPRODUCT(('sap nuevo'!H$2:H$9987="GALICIA")*('sap nuevo'!J$2:J$9987="fuera de fecha")*('sap nuevo'!F$2:F$9987>0)*('sap nuevo'!F$2:F$9987))} -> 19440860 | D39: —
A40: MACRO | B40: =COUNTIFS('sap nuevo'!H$2:H$9987,"MACRO",'sap nuevo'!J$2:J$9987,"fuera de fecha",'sap nuevo'!F$2:F$9987,">0") -> 30 | C40: {=SUMPRODUCT(('sap nuevo'!H$2:H$9987="MACRO")*('sap nuevo'!J$2:J$9987="fuera de fecha")*('sap nuevo'!F$2:F$9987>0)*('sap nuevo'!F$2:F$9987))} -> 4.8424951e+08 | D40: —
A41: HSBC | B41: =COUNTIFS('sap nuevo'!H$2:H$9987,"HSBC",'sap nuevo'!J$2:J$9987,"fuera de fecha",'sap nuevo'!F$2:F$9987,">0") -> 0 | C41: {=SUMPRODUCT(('sap nuevo'!H$2:H$9987="HSBC")*('sap nuevo'!J$2:J$9987="fuera de fecha")*('sap nuevo'!F$2:F$9987>0)*('sap nuevo'!F$2:F$9987))} -> 0 | D41: —
A42: TOTAL CADUCADOS | B42: =COUNTIFS('sap nuevo'!J$2:J$9987,"fuera de fecha",'sap nuevo'!F$2:F$9987,">0") -> 36 | C42: {=SUMPRODUCT(('sap nuevo'!J$2:J$9987="fuera de fecha")*('sap nuevo'!F$2:F$9987>0)*('sap nuevo'!F$2:F$9987))} -> 5.0369037e+08

Sheet ANALISIS
B1: CITRUSVIL S.A. — Análisis de Cheques
B2: =TODAY() -> 46272
K3: Año: | L3: 2026
B4: =" EMISIÓN MENSUAL — "&YEAR(TODAY()) -> EMISIÓN MENSUAL — 2026 | F4: RESUMEN ANUAL | J4: =" PLAZO PROM. COBRO POR MES — "&$L$3&" (días)" -> PLAZO PROM. COBRO POR MES — 2026 (días)
B5: Mes | C5: Cant. Cheques | D5: Importe Total ($) | F5: Año | G5: Cant. Cheques | H5: Importe Total ($) | J5: Mes | K5: Plazo Prom. (días) | L5: Nivel
B6: Enero | C6: {=SUMPRODUCT(('sap nuevo'!O$2:O$9987=1)*('sap nuevo'!P$2:P$9987=YEAR(TODAY()))*('sap nuevo'!F$2:F$9987>0))} -> 86 | D6: {=SUMPRODUCT(('sap nuevo'!O$2:O$9987=1)*('sap nuevo'!P$2:P$9987=YEAR(TODAY()))*('sap nuevo'!F$2:F$9987>0)*('sap nuevo'!F$2:F$9987))} -> 1.7218548e+09 | F6: =YEAR(TODAY())-2 -> 2024 | G6: {=SUMPRODUCT(('sap nuevo'!P$2:P$9987=YEAR(TODAY())-2)*('sap nuevo'!F$2:F$9987>0))} -> 0 | H6: {=SUMPRODUCT(('sap nuevo'!P$2:P$9987=YEAR(TODAY())-2)*('sap nuevo'!F$2:F$9987>0)*('sap nuevo'!F$2:F$9987))} -> 0 | J6: Enero | K6: {=IFERROR(SUMPRODUCT(('sap nuevo'!O$2:O$9987=1)*('sap nuevo'!P$2:P$9987=$L$3)*('sap nuevo'!J$2:J$9987="pagado")*('sap nuevo'!F$2:F$9987>0)*(IFERROR(DATEVALUE(_xlfn.XLOOKUP('sap nuevo'!E$2:E$9987,extracto!$C$2:$C$9999,extracto!$B$2:$B$9999))-'sap nuevo'!G$2:G$9987,0)))/SUMPRODUCT(('sap nuevo'!O$2:O$9987=1)*('sap nuevo'!P$2:P$9987=$L$3)*('sap nuevo'!J$2:J$9987="pagado")*('sap nuevo'!F$2:F$9987>0)*(ISNUMBER(DATEVALUE(_xlfn.XLOOKUP('sap nuevo'!E$2:E$9987,extracto!$C$2:$C$9999,extracto!$B$2:$B$9999))))),0)} -> 3.1176471 | L6: =IF(K6=0,"—",IF(K6>6,"▲ Alto",IF(K6>4,"● Medio","▼ Normal"))) -> ▼ Normal
B7: Febrero | C7: {=SUMPRODUCT(('sap nuevo'!O$2:O$9987=2)*('sap nuevo'!P$2:P$9987=YEAR(TODAY()))*('sap nuevo'!F$2:F$9987>0))} -> 57 | D7: {=SUMPRODUCT(('sap nuevo'!O$2:O$9987=2)*('sap nuevo'!P$2:P$9987=YEAR(TODAY()))*('sap nuevo'!F$2:F$9987>0)*('sap nuevo'!F$2:F$9987))} -> 1.5385154e+09 | F7: =YEAR(TODAY())-1 -> 2025 | G7: {=SUMPRODUCT(('sap nuevo'!P$2:P$9987=YEAR(TODAY())-1)*('sap nuevo'!F$2:F$9987>0))} -> 1493 | H7: {=SUMPRODUCT(('sap nuevo'!P$2:P$9987=YEAR(TODAY())-1)*('sap nuevo'!F$2:F$9987>0)*('sap nuevo'!F$2:F$9987))} -> 2.5274031e+10 | J7: Febrero | K7: {=IFERROR(SUMPRODUCT(('sap nuevo'!O$2:O$9987=2)*('sap nuevo'!P$2:P$9987=$L$3)*('sap nuevo'!J$2:J$9987="pagado")*('sap nuevo'!F$2:F$9987>0)*(IFERROR(DATEVALUE(_xlfn.XLOOKUP('sap nuevo'!E$2:E$9987,extracto!$C$2:$C$9999,extracto!$B$2:$B$9999))-'sap nuevo'!G$2:G$9987,0)))/SUMPRODUCT(('sap nuevo'!O$2:O$9987=2)*('sap nuevo'!P$2:P$9987=$L$3)*('sap nuevo'!J$2:J$9987="pagado")*('sap nuevo'!F$2:F$9987>0)*(ISNUMBER(DATEVALUE(_xlfn.XLOOKUP('sap nuevo'!E$2:E$9987,extracto!$C$2:$C$9999,extracto!$B$2:$B$9999))))),0)} -> 4.125 | L7: =IF(K7=0,"—",IF(K7>6,"▲ Alto",IF(K7>4,"● Medio","▼ Normal"))) -> ● Medio
B8: Marzo | C8: {=SUMPRODUCT(('sap nuevo'!O$2:O$9987=3)*('sap nuevo'!P$2:P$9987=YEAR(TODAY()))*('sap nuevo'!F$2:F$9987>0))} -> 78 | D8: {=SUMPRODUCT(('sap nuevo'!O$2:O$9987=3)*('sap nuevo'!P$2:P$9987=YEAR(TODAY()))*('sap nuevo'!F$2:F$9987>0)*('sap nuevo'!F$2:F$9987))} -> 1.8311845e+09 | F8: =YEAR(TODAY()) -> 2026 | G8: {=SUMPRODUCT(('sap nuevo'!P$2:P$9987=YEAR(TODAY()))*('sap nuevo'!F$2:F$9987>0))} -> 873 | H8: {=SUMPRODUCT(('sap nuevo'!P$2:P$9987=YEAR(TODAY()))*('sap nuevo'!F$2:F$9987>0)*('sap nuevo'!F$2:F$9987))} -> 1.454825e+10 | J8: Marzo | K8: {=IFERROR(SUMPRODUCT(('sap nuevo'!O$2:O$9987=3)*('sap nuevo'!P$2:P$9987=$L$3)*('sap nuevo'!J$2:J$9987="pagado")*('sap nuevo'!F$2:F$9987>0)*(IFERROR(DATEVALUE(_xlfn.XLOOKUP('sap nuevo'!E$2:E$9987,extracto!$C$2:$C$9999,extracto!$B$2:$B$9999))-'sap nuevo'!G$2:G$9987,0)))/SUMPRODUCT(('sap nuevo'!O$2:O$9987=3)*('sap nuevo'!P$2:P$9987=$L$3)*('sap nuevo'!J$2:J$9987="pagado")*('sap nuevo'!F$2:F$9987>0)*(ISNUMBER(DATEVALUE(_xlfn.XLOOKUP('sap nuevo'!E$2:E$9987,extracto!$C$2:$C$9999,extracto!$B$2:$B$9999))))),0)} -> 4.1081081 | L8: =IF(K8=0,"—",IF(K8>6,"▲ Alto",IF(K8>4,"● Medio","▼ Normal"))) -> ● Medio
B9: Abril | C9: {=SUMPRODUCT(('sap nuevo'!O$2:O$9987=4)*('sap nuevo'!P$2:P$9987=YEAR(TODAY()))*('sap nuevo'!F$2:F$9987>0))} -> 95 | D9: {=SUMPRODUCT(('sap nuevo'!O$2:O$9987=4)*('sap nuevo'!P$2:P$9987=YEAR(TODAY()))*('sap nuevo'!F$2:F$9987>0)*('sap nuevo'!F$2:F$9987))} -> 1.8762526e+09 | F9: TOTAL | G9: =SUM(G6:G8) -> 2366 | H9: =SUM(H6:H8) -> 3.9822281e+10 | J9: Abril | K9: {=IFERROR(SUMPRODUCT(('sap nuevo'!O$2:O$9987=4)*('sap nuevo'!P$2:P$9987=$L$3)*('sap nuevo'!J$2:J$9987="pagado")*('sap nuevo'!F$2:F$9987>0)*(IFERROR(DATEVALUE(_xlfn.XLOOKUP('sap nuevo'!E$2:E$9987,extracto!$C$2:$C$9999,extracto!$B$2:$B$9999))-'sap nuevo'!G$2:G$9987,0)))/SUMPRODUCT(('sap nuevo'!O$2:O$9987=4)*('sap nuevo'!P$2:P$9987=$L$3)*('sap nuevo'!J$2:J$9987="pagado")*('sap nuevo'!F$2:F$9987>0)*(ISNUMBER(DATEVALUE(_xlfn.XLOOKUP('sap nuevo'!E$2:E$9987,extracto!$C$2:$C$9999,extracto!$B$2:$B$9999))))),0)} -> 3 | L9: =IF(K9=0,"—",IF(K9>6,"▲ Alto",IF(K9>4,"● Medio","▼ Normal"))) -> ▼ Normal
B10: Mayo | C10: {=SUMPRODUCT(('sap nuevo'!O$2:O$9987=5)*('sap nuevo'!P$2:P$9987=YEAR(TODAY()))*('sap nuevo'!F$2:F$9987>0))} -> 131 | D10: {=SUMPRODUCT(('sap nuevo'!O$2:O$9987=5)*('sap nuevo'!P$2:P$9987=YEAR(TODAY()))*('sap nuevo'!F$2:F$9987>0)*('sap nuevo'!F$2:F$9987))} -> 1.7058597e+09 | J10: Mayo | K10: {=IFERROR(SUMPRODUCT(('sap nuevo'!O$2:O$9987=5)*('sap nuevo'!P$2:P$9987=$L$3)*('sap nuevo'!J$2:J$9987="pagado")*('sap nuevo'!F$2:F$9987>0)*(IFERROR(DATEVALUE(_xlfn.XLOOKUP('sap nuevo'!E$2:E$9987,extracto!$C$2:$C$9999,extracto!$B$2:$B$9999))-'sap nuevo'!G$2:G$9987,0)))/SUMPRODUCT(('sap nuevo'!O$2:O$9987=5)*('sap nuevo'!P$2:P$9987=$L$3)*('sap nuevo'!J$2:J$9987="pagado")*('sap nuevo'!F$2:F$9987>0)*(ISNUMBER(DATEVALUE(_xlfn.XLOOKUP('sap nuevo'!E$2:E$9987,extracto!$C$2:$C$9999,extracto!$B$2:$B$9999))))),0)} -> 11 | L10: =IF(K10=0,"—",IF(K10>6,"▲ Alto",IF(K10>4,"● Medio","▼ Normal"))) -> ▲ Alto
B11: Junio | C11: {=SUMPRODUCT(('sap nuevo'!O$2:O$9987=6)*('sap nuevo'!P$2:P$9987=YEAR(TODAY()))*('sap nuevo'!F$2:F$9987>0))} -> 103 | D11: {=SUMPRODUCT(('sap nuevo'!O$2:O$9987=6)*('sap nuevo'!P$2:P$9987=YEAR(TODAY()))*('sap nuevo'!F$2:F$9987>0)*('sap nuevo'!F$2:F$9987))} -> 1.2604856e+09 | F11: DISTRIBUCIÓN POR BANCO | J11: Junio | K11: {=IFERROR(SUMPRODUCT(('sap nuevo'!O$2:O$9987=6)*('sap nuevo'!P$2:P$9987=$L$3)*('sap nuevo'!J$2:J$9987="pagado")*('sap nuevo'!F$2:F$9987>0)*(IFERROR(DATEVALUE(_xlfn.XLOOKUP('sap nuevo'!E$2:E$9987,extracto!$C$2:$C$9999,extracto!$B$2:$B$9999))-'sap nuevo'!G$2:G$9987,0)))/SUMPRODUCT(('sap nuevo'!O$2:O$9987=6)*('sap nuevo'!P$2:P$9987=$L$3)*('sap nuevo'!J$2:J$9987="pagado")*('sap nuevo'!F$2:F$9987>0)*(ISNUMBER(DATEVALUE(_xlfn.XLOOKUP('sap nuevo'!E$2:E$9987,extracto!$C$2:$C$9999,extracto!$B$2:$B$9999))))),0)} -> 3.8349515 | L11: =IF(K11=0,"—",IF(K11>6,"▲ Alto",IF(K11>4,"● Medio","▼ Normal"))) -> ▼ Normal
B12: Julio | C12: {=SUMPRODUCT(('sap nuevo'!O$2:O$9987=7)*('sap nuevo'!P$2:P$9987=YEAR(TODAY()))*('sap nuevo'!F$2:F$9987>0))} -> 142 | D12: {=SUMPRODUCT(('sap nuevo'!O$2:O$9987=7)*('sap nuevo'!P$2:P$9987=YEAR(TODAY()))*('sap nuevo'!F$2:F$9987>0)*('sap nuevo'!F$2:F$9987))} -> 1.9775059e+09 | F12: Banco | G12: Cant. Cheques | H12: Importe Total ($) | J12: Julio | K12: {=IFERROR(SUMPRODUCT(('sap nuevo'!O$2:O$9987=7)*('sap nuevo'!P$2:P$9987=$L$3)*('sap nuevo'!J$2:J$9987="pagado")*('sap nuevo'!F$2:F$9987>0)*(IFERROR(DATEVALUE(_xlfn.XLOOKUP('sap nuevo'!E$2:E$9987,extracto!$C$2:$C$9999,extracto!$B$2:$B$9999))-'sap nuevo'!G$2:G$9987,0)))/SUMPRODUCT(('sap nuevo'!O$2:O$9987=7)*('sap nuevo'!P$2:P$9987=$L$3)*('sap nuevo'!J$2:J$9987="pagado")*('sap nuevo'!F$2:F$9987>0)*(ISNUMBER(DATEVALUE(_xlfn.XLOOKUP('sap nuevo'!E$2:E$9987,extracto!$C$2:$C$9999,extracto!$B$2:$B$9999))))),0)} -> 3.6737589 | L12: =IF(K12=0,"—",IF(K12>6,"▲ Alto",IF(K12>4,"● Medio","▼ Normal"))) -> ▼ Normal
B13: Agosto | C13: {=SUMPRODUCT(('sap nuevo'!O$2:O$9987=8)*('sap nuevo'!P$2:P$9987=YEAR(TODAY()))*('sap nuevo'!F$2:F$9987>0))} -> 141 | D13: {=SUMPRODUCT(('sap nuevo'!O$2:O$9987=8)*('sap nuevo'!P$2:P$9987=YEAR(TODAY()))*('sap nuevo'!F$2:F$9987>0)*('sap nuevo'!F$2:F$9987))} -> 2.1196716e+09 | F13: GALICIA | G13: =COUNTIFS('sap nuevo'!H$2:H$9987,"GALICIA",'sap nuevo'!F$2:F$9987,">0") -> 783 | H13: =SUMIF('sap nuevo'!H$2:H$9987,"GALICIA",'sap nuevo'!F$2:F$9987) -> 1.5310033e+10 | J13: Agosto | K13: {=IFERROR(SUMPRODUCT(('sap nuevo'!O$2:O$9987=8)*('sap nuevo'!P$2:P$9987=$L$3)*('sap nuevo'!J$2:J$9987="pagado")*('sap nuevo'!F$2:F$9987>0)*(IFERROR(DATEVALUE(_xlfn.XLOOKUP('sap nuevo'!E$2:E$9987,extracto!$C$2:$C$9999,extracto!$B$2:$B$9999))-'sap nuevo'!G$2:G$9987,0)))/SUMPRODUCT(('sap nuevo'!O$2:O$9987=8)*('sap nuevo'!P$2:P$9987=$L$3)*('sap nuevo'!J$2:J$9987="pagado")*('sap nuevo'!F$2:F$9987>0)*(ISNUMBER(DATEVALUE(_xlfn.XLOOKUP('sap nuevo'!E$2:E$9987,extracto!$C$2:$C$9999,extracto!$B$2:$B$9999))))),0)} -> 2.4338235 | L13: =IF(K13=0,"—",IF(K13>6,"▲ Alto",IF(K13>4,"● Medio","▼ Normal"))) -> ▼ Normal
B14: Septiembre | C14: {=SUMPRODUCT(('sap nuevo'!O$2:O$9987=9)*('sap nuevo'!P$2:P$9987=YEAR(TODAY()))*('sap nuevo'!F$2:F$9987>0))} -> 34 | D14: {=SUMPRODUCT(('sap nuevo'!O$2:O$9987=9)*('sap nuevo'!P$2:P$9987=YEAR(TODAY()))*('sap nuevo'!F$2:F$9987>0)*('sap nuevo'!F$2:F$9987))} -> 4.7465788e+08 | F14: MACRO | G14: =COUNTIFS('sap nuevo'!H$2:H$9987,"MACRO",'sap nuevo'!F$2:F$9987,">0") -> 1449 | H14: =SUMIF('sap nuevo'!H$2:H$9987,"MACRO",'sap nuevo'!F$2:F$9987) -> 2.1831949e+10 | J14: Septiembre | K14: {=IFERROR(SUMPRODUCT(('sap nuevo'!O$2:O$9987=9)*('sap nuevo'!P$2:P$9987=$L$3)*('sap nuevo'!J$2:J$9987="pagado")*('sap nuevo'!F$2:F$9987>0)*(IFERROR(DATEVALUE(_xlfn.XLOOKUP('sap nuevo'!E$2:E$9987,extracto!$C$2:$C$9999,extracto!$B$2:$B$9999))-'sap nuevo'!G$2:G$9987,0)))/SUMPRODUCT(('sap nuevo'!O$2:O$9987=9)*('sap nuevo'!P$2:P$9987=$L$3)*('sap nuevo'!J$2:J$9987="pagado")*('sap nuevo'!F$2:F$9987>0)*(ISNUMBER(DATEVALUE(_xlfn.XLOOKUP('sap nuevo'!E$2:E$9987,extracto!$C$2:$C$9999,extracto!$B$2:$B$9999))))),0)} -> 0.90909091 | L14: =IF(K14=0,"—",IF(K14>6,"▲ Alto",IF(K14>4,"● Medio","▼ Normal"))) -> ▼ Normal
B15: Octubre | C15: {=SUMPRODUCT(('sap nuevo'!O$2:O$9987=10)*('sap nuevo'!P$2:P$9987=YEAR(TODAY()))*('sap nuevo'!F$2:F$9987>0))} -> 4 | D15: {=SUMPRODUCT(('sap nuevo'!O$2:O$9987=10)*('sap nuevo'!P$2:P$9987=YEAR(TODAY()))*('sap nuevo'!F$2:F$9987>0)*('sap nuevo'!F$2:F$9987))} -> 28903022 | F15: HSBC | G15: =COUNTIFS('sap nuevo'!H$2:H$9987,"HSBC",'sap nuevo'!F$2:F$9987,">0") -> 134 | H15: =SUMIF('sap nuevo'!H$2:H$9987,"HSBC",'sap nuevo'!F$2:F$9987) -> 2.6802994e+09 | J15: Octubre | K15: {=IFERROR(SUMPRODUCT(('sap nuevo'!O$2:O$9987=10)*('sap nuevo'!P$2:P$9987=$L$3)*('sap nuevo'!J$2:J$9987="pagado")*('sap nuevo'!F$2:F$9987>0)*(IFERROR(DATEVALUE(_xlfn.XLOOKUP('sap nuevo'!E$2:E$9987,extracto!$C$2:$C$9999,extracto!$B$2:$B$9999))-'sap nuevo'!G$2:G$9987,0)))/SUMPRODUCT(('sap nuevo'!O$2:O$9987=10)*('sap nuevo'!P$2:P$9987=$L$3)*('sap nuevo'!J$2:J$9987="pagado")*('sap nuevo'!F$2:F$9987>0)*(ISNUMBER(DATEVALUE(_xlfn.XLOOKUP('sap nuevo'!E$2:E$9987,extracto!$C$2:$C$9999,extracto!$B$2:$B$9999))))),0)} -> 0 | L15: =IF(K15=0,"—",IF(K15>6,"▲ Alto",IF(K15>4,"● Medio","▼ Normal"))) -> —
B16: Noviembre | C16: {=SUMPRODUCT(('sap nuevo'!O$2:O$9987=11)*('sap nuevo'!P$2:P$9987=YEAR(TODAY()))*('sap nuevo'!F$2:F$9987>0))} -> 2 | D16: {=SUMPRODUCT(('sap nuevo'!O$2:O$9987=11)*('sap nuevo'!P$2:P$9987=YEAR(TODAY()))*('sap nuevo'!F$2:F$9987>0)*('sap nuevo'!F$2:F$9987))} -> 13358937 | F16: TOTAL | G16: =COUNTIF('sap nuevo'!F$2:F$9987,">0") -> 2366 | H16: =SUMIF('sap nuevo'!F$2:F$9987,">0",'sap nuevo'!F$2:F$9987) -> 3.9822281e+10 | J16: Noviembre | K16: {=IFERROR(SUMPRODUCT(('sap nuevo'!O$2:O$9987=11)*('sap nuevo'!P$2:P$9987=$L$3)*('sap nuevo'!J$2:J$9987="pagado")*('sap nuevo'!F$2:F$9987>0)*(IFERROR(DATEVALUE(_xlfn.XLOOKUP('sap nuevo'!E$2:E$9987,extracto!$C$2:$C$9999,extracto!$B$2:$B$9999))-'sap nuevo'!G$2:G$9987,0)))/SUMPRODUCT(('sap nuevo'!O$2:O$9987=11)*('sap nuevo'!P$2:P$9987=$L$3)*('sap nuevo'!J$2:J$9987="pagado")*('sap nuevo'!F$2:F$9987>0)*(ISNUMBER(DATEVALUE(_xlfn.XLOOKUP('sap nuevo'!E$2:E$9987,extracto!$C$2:$C$9999,extracto!$B$2:$B$9999))))),0)} -> 0 | L16: =IF(K16=0,"—",IF(K16>6,"▲ Alto",IF(K16>4,"● Medio","▼ Normal"))) -> —
B17: Diciembre | C17: {=SUMPRODUCT(('sap nuevo'!O$2:O$9987=12)*('sap nuevo'!P$2:P$9987=YEAR(TODAY()))*('sap nuevo'!F$2:F$9987>0))} -> 0 | D17: {=SUMPRODUCT(('sap nuevo'!O$2:O$9987=12)*('sap nuevo'!P$2:P$9987=YEAR(TODAY()))*('sap nuevo'!F$2:F$9987>0)*('sap nuevo'!F$2:F$9987))} -> 0 | J17: Diciembre | K17: {=IFERROR(SUMPRODUCT(('sap nuevo'!O$2:O$9987=12)*('sap nuevo'!P$2:P$9987=$L$3)*('sap nuevo'!J$2:J$9987="pagado")*('sap nuevo'!F$2:F$9987>0)*(IFERROR(DATEVALUE(_xlfn.XLOOKUP('sap nuevo'!E$2:E$9987,extracto!$C$2:$C$9999,extracto!$B$2:$B$9999))-'sap nuevo'!G$2:G$9987,0)))/SUMPRODUCT(('sap nuevo'!O$2:O$9987=12)*('sap nuevo'!P$2:P$9987=$L$3)*('sap nuevo'!J$2:J$9987="pagado")*('sap nuevo'!F$2:F$9987>0)*(ISNUMBER(DATEVALUE(_xlfn.XLOOKUP('sap nuevo'!E$2:E$9987,extracto!$C$2:$C$9999,extracto!$B$2:$B$9999))))),0)} -> 0 | L17: =IF(K17=0,"—",IF(K17>6,"▲ Alto",IF(K17>4,"● Medio","▼ Normal"))) -> —
B18: ="TOTAL "&YEAR(TODAY()) -> TOTAL 2026 | C18: =SUM(C6:C17) -> 873 | D18: =SUM(D6:D17) -> 1.454825e+10 | F18: PLAZO PROMEDIO DE COBRO POR BANCO (días)
F19: Banco | G19: Cheques Pagados | H19: Plazo Prom. (días) | J19: CHEQUES CADUCADOS / FUERA DE FECHA
B20: =" EMISIÓN MENSUAL — "&(YEAR(TODAY())-1) -> EMISIÓN MENSUAL — 2025 | F20: GALICIA | G20: =COUNTIFS('sap nuevo'!H$2:H$9987,"GALICIA",'sap nuevo'!J$2:J$9987,"pagado",'sap nuevo'!F$2:F$9987,">0") -> 777 | H20: {=IFERROR(SUMPRODUCT(('sap nuevo'!H$2:H$9987="GALICIA")*('sap nuevo'!J$2:J$9987="pagado")*('sap nuevo'!F$2:F$9987>0)*('sap nuevo'!G$2:G$9987-'sap nuevo'!B$2:B$9987))/G20,"-")} -> 4.5070785 | J20: Banco | K20: Cantidad | L20: Importe Total ($)
B21: Mes | C21: Cant. Cheques | D21: Importe Total ($) | F21: MACRO | G21: =COUNTIFS('sap nuevo'!H$2:H$9987,"MACRO",'sap nuevo'!J$2:J$9987,"pagado",'sap nuevo'!F$2:F$9987,">0") -> 1385 | H21: {=IFERROR(SUMPRODUCT(('sap nuevo'!H$2:H$9987="MACRO")*('sap nuevo'!J$2:J$9987="pagado")*('sap nuevo'!F$2:F$9987>0)*('sap nuevo'!G$2:G$9987-'sap nuevo'!B$2:B$9987))/G21,"-")} -> 4.867148 | J21: GALICIA | K21: =COUNTIFS('sap nuevo'!H$2:H$9987,"GALICIA",'sap nuevo'!J$2:J$9987,"fuera de fecha",'sap nuevo'!F$2:F$9987,">0") -> 6 | L21: {=SUMPRODUCT(('sap nuevo'!H$2:H$9987="GALICIA")*('sap nuevo'!J$2:J$9987="fuera de fecha")*('sap nuevo'!F$2:F$9987>0)*('sap nuevo'!F$2:F$9987))} -> 19440860
B22: Enero | C22: {=SUMPRODUCT(('sap nuevo'!O$2:O$9987=1)*('sap nuevo'!P$2:P$9987=YEAR(TODAY())-1)*('sap nuevo'!F$2:F$9987>0))} -> 57 | D22: {=SUMPRODUCT(('sap nuevo'!O$2:O$9987=1)*('sap nuevo'!P$2:P$9987=YEAR(TODAY())-1)*('sap nuevo'!F$2:F$9987>0)*('sap nuevo'!F$2:F$9987))} -> 9.9953956e+08 | F22: HSBC | G22: =COUNTIFS('sap nuevo'!H$2:H$9987,"HSBC",'sap nuevo'!J$2:J$9987,"pagado",'sap nuevo'!F$2:F$9987,">0") -> 134 | H22: {=IFERROR(SUMPRODUCT(('sap nuevo'!H$2:H$9987="HSBC")*('sap nuevo'!J$2:J$9987="pagado")*('sap nuevo'!F$2:F$9987>0)*('sap nuevo'!G$2:G$9987-'sap nuevo'!B$2:B$9987))/G22,"-")} -> 2.380597 | J22: MACRO | K22: =COUNTIFS('sap nuevo'!H$2:H$9987,"MACRO",'sap nuevo'!J$2:J$9987,"fuera de fecha",'sap nuevo'!F$2:F$9987,">0") -> 30 | L22: {=SUMPRODUCT(('sap nuevo'!H$2:H$9987="MACRO")*('sap nuevo'!J$2:J$9987="fuera de fecha")*('sap nuevo'!F$2:F$9987>0)*('sap nuevo'!F$2:F$9987))} -> 4.8424951e+08
B23: Febrero | C23: {=SUMPRODUCT(('sap nuevo'!O$2:O$9987=2)*('sap nuevo'!P$2:P$9987=YEAR(TODAY())-1)*('sap nuevo'!F$2:F$9987>0))} -> 52 | D23: {=SUMPRODUCT(('sap nuevo'!O$2:O$9987=2)*('sap nuevo'!P$2:P$9987=YEAR(TODAY())-1)*('sap nuevo'!F$2:F$9987>0)*('sap nuevo'!F$2:F$9987))} -> 8.1115981e+08 | F23: PROMEDIO GENERAL | G23: =COUNTIFS('sap nuevo'!J$2:J$9987,"pagado",'sap nuevo'!F$2:F$9987,">0") -> 2296 | H23: {=IFERROR(SUMPRODUCT(('sap nuevo'!J$2:J$9987="pagado")*('sap nuevo'!F$2:F$9987>0)*('sap nuevo'!G$2:G$9987-'sap nuevo'!B$2:B$9987))/G23,"-")} -> 4.6001742 | J23: HSBC | K23: =COUNTIFS('sap nuevo'!H$2:H$9987,"HSBC",'sap nuevo'!J$2:J$9987,"fuera de fecha",'sap nuevo'!F$2:F$9987,">0") -> 0 | L23: {=SUMPRODUCT(('sap nuevo'!H$2:H$9987="HSBC")*('sap nuevo'!J$2:J$9987="fuera de fecha")*('sap nuevo'!F$2:F$9987>0)*('sap nuevo'!F$2:F$9987))} -> 0
B24: Marzo | C24: {=SUMPRODUCT(('sap nuevo'!O$2:O$9987=3)*('sap nuevo'!P$2:P$9987=YEAR(TODAY())-1)*('sap nuevo'!F$2:F$9987>0))} -> 71 | D24: {=SUMPRODUCT(('sap nuevo'!O$2:O$9987=3)*('sap nuevo'!P$2:P$9987=YEAR(TODAY())-1)*('sap nuevo'!F$2:F$9987>0)*('sap nuevo'!F$2:F$9987))} -> 9.9117268e+08 | J24: TOTAL CADUCADOS | K24: =SUM(K21:K23) -> 36 | L24: =SUM(L21:L23) -> 5.0369037e+08
B25: Abril | C25: {=SUMPRODUCT(('sap nuevo'!O$2:O$9987=4)*('sap nuevo'!P$2:P$9987=YEAR(TODAY())-1)*('sap nuevo'!F$2:F$9987>0))} -> 102 | D25: {=SUMPRODUCT(('sap nuevo'!O$2:O$9987=4)*('sap nuevo'!P$2:P$9987=YEAR(TODAY())-1)*('sap nuevo'!F$2:F$9987>0)*('sap nuevo'!F$2:F$9987))} -> 1.233805e+09
B26: Mayo | C26: {=SUMPRODUCT(('sap nuevo'!O$2:O$9987=5)*('sap nuevo'!P$2:P$9987=YEAR(TODAY())-1)*('sap nuevo'!F$2:F$9987>0))} -> 144 | D26: {=SUMPRODUCT(('sap nuevo'!O$2:O$9987=5)*('sap nuevo'!P$2:P$9987=YEAR(TODAY())-1)*('sap nuevo'!F$2:F$9987>0)*('sap nuevo'!F$2:F$9987))} -> 2.0593899e+09
B27: Junio | C27: {=SUMPRODUCT(('sap nuevo'!O$2:O$9987=6)*('sap nuevo'!P$2:P$9987=YEAR(TODAY())-1)*('sap nuevo'!F$2:F$9987>0))} -> 155 | D27: {=SUMPRODUCT(('sap nuevo'!O$2:O$9987=6)*('sap nuevo'!P$2:P$9987=YEAR(TODAY())-1)*('sap nuevo'!F$2:F$9987>0)*('sap nuevo'!F$2:F$9987))} -> 1.7804621e+09
B28: Julio | C28: {=SUMPRODUCT(('sap nuevo'!O$2:O$9987=7)*('sap nuevo'!P$2:P$9987=YEAR(TODAY())-1)*('sap nuevo'!F$2:F$9987>0))} -> 243 | D28: {=SUMPRODUCT(('sap nuevo'!O$2:O$9987=7)*('sap nuevo'!P$2:P$9987=YEAR(TODAY())-1)*('sap nuevo'!F$2:F$9987>0)*('sap nuevo'!F$2:F$9987))} -> 3.8924914e+09
B29: Agosto | C29: {=SUMPRODUCT(('sap nuevo'!O$2:O$9987=8)*('sap nuevo'!P$2:P$9987=YEAR(TODAY())-1)*('sap nuevo'!F$2:F$9987>0))} -> 174 | D29: {=SUMPRODUCT(('sap nuevo'!O$2:O$9987=8)*('sap nuevo'!P$2:P$9987=YEAR(TODAY())-1)*('sap nuevo'!F$2:F$9987>0)*('sap nuevo'!F$2:F$9987))} -> 2.1720285e+09
B30: Septiembre | C30: {=SUMPRODUCT(('sap nuevo'!O$2:O$9987=9)*('sap nuevo'!P$2:P$9987=YEAR(TODAY())-1)*('sap nuevo'!F$2:F$9987>0))} -> 179 | D30: {=SUMPRODUCT(('sap nuevo'!O$2:O$9987=9)*('sap nuevo'!P$2:P$9987=YEAR(TODAY())-1)*('sap nuevo'!F$2:F$9987>0)*('sap nuevo'!F$2:F$9987))} -> 3.2812237e+09
B31: Octubre | C31: {=SUMPRODUCT(('sap nuevo'!O$2:O$9987=10)*('sap nuevo'!P$2:P$9987=YEAR(TODAY())-1)*('sap nuevo'!F$2:F$9987>0))} -> 140 | D31: {=SUMPRODUCT(('sap nuevo'!O$2:O$9987=10)*('sap nuevo'!P$2:P$9987=YEAR(TODAY())-1)*('sap nuevo'!F$2:F$9987>0)*('sap nuevo'!F$2:F$9987))} -> 3.4447589e+09
B32: Noviembre | C32: {=SUMPRODUCT(('sap nuevo'!O$2:O$9987=11)*('sap nuevo'!P$2:P$9987=YEAR(TODAY())-1)*('sap nuevo'!F$2:F$9987>0))} -> 83 | D32: {=SUMPRODUCT(('sap nuevo'!O$2:O$9987=11)*('sap nuevo'!P$2:P$9987=YEAR(TODAY())-1)*('sap nuevo'!F$2:F$9987>0)*('sap nuevo'!F$2:F$9987))} -> 2.2338796e+09
B33: Diciembre | C33: {=SUMPRODUCT(('sap nuevo'!O$2:O$9987=12)*('sap nuevo'!P$2:P$9987=YEAR(TODAY())-1)*('sap nuevo'!F$2:F$9987>0))} -> 93 | D33: {=SUMPRODUCT(('sap nuevo'!O$2:O$9987=12)*('sap nuevo'!P$2:P$9987=YEAR(TODAY())-1)*('sap nuevo'!F$2:F$9987>0)*('sap nuevo'!F$2:F$9987))} -> 2.3741201e+09
B34: ="TOTAL "&(YEAR(TODAY())-1) -> TOTAL 2025 | C34: =SUM(C22:C33) -> 1493 | D34: =SUM(D22:D33) -> 2.5274031e+10
